Workbook

Sheet OVERVIEW
B1: OVERVIEW
A2: ITEM | B2: # TOTAL | C2: TOTAL COST VALUE | D2: # SOLD THIS MONTH | E2: SOLD RETAIL VALUE THIS MONTH | F2: # PENDING | G2: PENDING COST VALUE | H2: # AVAILABLE STOCK | I2: AVAILABLE STOCK VALUE
A3: Profit & Loss Explination
A4: STOCK
A5: TOTAL STOCK | B5: ='STOCK OVERVIEW'!B10 -> 2114 | C5: ='STOCK OVERVIEW'!C10 -> 2098139.5 | D5: ='TOTAL OFFICE STOCK'!C22 -> 360 | E5: ='TOTAL OFFICE STOCK'!G22 -> 224661.1 | F5: ='TOTAL OFFICE STOCK'!D22 -> 44 | G5: ='TOTAL OFFICE STOCK'!H22 -> 24677.5 | H5: ='TOTAL OFFICE STOCK'!E22 -> 650 | I5: ='TOTAL OFFICE STOCK'!I22 -> 449941.02
A6: COSTS
A7: FIXED COSTS THIS MONTH
A8: EXPENSES THIS MONTH
A9: MARKETING COSTS THIS MONTH
A10: INCOME
A11: INCOME THIS MONTH
A12: P&L
A13: PROFIT / LOSS THIS MONTH

Sheet STOCK OVERVIEW
A1: TOTAL STOCK OVERVIEW
A2: ITEM | B2: # TOTAL | C2: TOTAL COST VALUE | D2: # SOLD | E2: SOLD COST VALUE | F2: # PENDING | G2: PENDING COST VALUE | H2: # AVAILABLE STOCK | I2: AVAILABLE STOCK VALUE | J2: NET PROFIT AFTER COST
A3: ='TOTAL OFFICE STOCK'!A22 -> SILK TOTAL | B3: ='TOTAL OFFICE STOCK'!B22 -> 1054 | C3: ='TOTAL OFFICE STOCK'!F22 -> 699279.62 | D3: ='TOTAL OFFICE STOCK'!C22 -> 360 | E3: ='TOTAL OFFICE STOCK'!G22 -> 224661.1 | F3: ='TOTAL OFFICE STOCK'!D22 -> 44 | G3: ='TOTAL OFFICE STOCK'!H22 -> 24677.5 | H3: ='TOTAL OFFICE STOCK'!E22 -> 650 | I3: ='TOTAL OFFICE STOCK'!I22 -> 449941.02 | J3: ='SILK - SOLD'!K5 -> 210978.91
A4: ='TOTAL OFFICE STOCK'!A30 -> RICCIARINI CORD LACE (70) | B4: ='TOTAL OFFICE STOCK'!B30 -> 70 | C4: ='LACE - STOCK OVERVIEW'!E7 -> 9900 | D4: ='TOTAL OFFICE STOCK'!C30 -> 0 | E4: ='LACE - STOCK OVERVIEW'!G7 -> 0 | F4: ='TOTAL OFFICE STOCK'!D30 -> 0 | G4: ='TOTAL OFFICE STOCK'!H30 -> 0 | H4: ='TOTAL OFFICE STOCK'!E30 -> 70 | I4: ='TOTAL OFFICE STOCK'!I30 -> 9900
A5: ='TOTAL OFFICE STOCK'!A28 -> LACE TOTAL | B5: ='TOTAL OFFICE STOCK'!B28 -> 182 | C5: ='TOTAL OFFICE STOCK'!F28 -> 179314.59 | D5: ='TOTAL OFFICE STOCK'!C28 -> 51 | E5: ='TOTAL OFFICE STOCK'!G28 -> 48205.59 | F5: ='TOTAL OFFICE STOCK'!D28 -> 4 | G5: ='TOTAL OFFICE STOCK'!H28 -> 3405.5 | H5: ='TOTAL OFFICE STOCK'!E28 -> 127 | I5: ='TOTAL OFFICE STOCK'!I28 -> 127703.5
A6: ='TOTAL OFFICE STOCK'!A38 -> LACE (CEMB) TOTAL | B6: ='TOTAL OFFICE STOCK'!B38 -> 396 | C6: ='TOTAL OFFICE STOCK'!F38 -> 145857.8 | D6: ='TOTAL OFFICE STOCK'!C38 -> 32 | E6: ='TOTAL OFFICE STOCK'!G38 -> 13556.55 | F6: ='TOTAL OFFICE STOCK'!D38 -> 0 | G6: ='TOTAL OFFICE STOCK'!H38 -> 0 | H6: ='TOTAL OFFICE STOCK'!E38 -> 364 | I6: ='TOTAL OFFICE STOCK'!I38 -> 132301.25
A7: ='TOTAL OFFICE STOCK'!A43 -> BEIRUT TOTAL | B7: ='TOTAL OFFICE STOCK'!B43 -> 95 | C7: ='LACE - STOCK OVERVIEW'!E6 -> 135555 | D7: ='TOTAL OFFICE STOCK'!C43 -> 2 | E7: ='TOTAL OFFICE STOCK'!G43 -> 1920 | F7: ='TOTAL OFFICE STOCK'!D43 -> 0 | G7: ='TOTAL OFFICE STOCK'!H43 -> 0 | H7: ='TOTAL OFFICE STOCK'!E43 -> 93 | I7: ='TOTAL OFFICE STOCK'!I43 -> 136515
A8: ='TOTAL OFFICE STOCK'!A75 -> EMBROIDERY TOTAL | B8: ='TOTAL OFFICE STOCK'!B75 -> 317 | C8: ='EMBROIDERY - STOCK OVERVIEW'!F34 -> 928232.5 | D8: ='TOTAL OFFICE STOCK'!C75 -> 10 | E8: ='TOTAL OFFICE STOCK'!G75 -> 31825 | F8: ='TOTAL OFFICE STOCK'!D75 -> 0 | G8: ='TOTAL OFFICE STOCK'!H75 -> 0 | H8: ='TOTAL OFFICE STOCK'!E75 -> 307 | I8: ='TOTAL OFFICE STOCK'!I75 -> 911187.5
A10: TOTAL | B10: =SUM(B3:B9) -> 2114 | C10: =SUM(C3:C9) -> 2098139.5 | D10: =SUM(D3:D9) -> 455 | E10: =SUM(E3:E9) -> 320168.24 | F10: =SUM(F3:F9) -> 48 | G10: =SUM(G3:G9) -> 28083 | H10: =SUM(H3:H9) -> 1611 | I10: =SUM(I3:I9) -> 1767548.3 | J10: =SUM(J3:J9) -> 210978.91
A13: PENDING | B13: # TOTAL | C13: TOTAL COST VALUE
A15: TOTAL | B15: ='TOTAL OFFICE STOCK'!B91 -> 0 | C15: ='TOTAL OFFICE STOCK'!F91 -> 100906.03

Sheet TOTAL OFFICE STOCK
A1: OFFICE STOCK REPORT
A2: ITEM | B2: # TOTAL | C2: # SOLD | D2: # PENDING | E2: # AVAILABLE STOCK | F2: TOTAL COST VALUE | G2: SOLD COST VALUE | H2: PENDING COST VALUE | I2: AVAILABLE STOCK COST VALUE
A3: 1. SILK
A4: M&M 1-70 | B4: =E4+D4+C4 -> 139 | C4: ='SILK - SOLD'!C79 -> 65 | D4: ='SILK - PENDING'!D18 -> 4 | E4: =M7M_A[[#Totals],[QUALITY]] -> 70 | F4: =G4+H4+I4 -> 80224 | G4: ='SILK - SOLD'!K79 -> 37198 | H4: ='SILK - PENDING'!H18 -> 2778 | I4: ='SILK - ALL'!H83 -> 40248
A5: ARGOMENTI (ARGO) | B5: =E5+D5+C5 -> 122 | C5: ='SILK - SOLD'!C107 -> 21 | D5: ='SILK - PENDING'!D27 -> 0 | E5: =ARGO_A[[#Totals],[QUALITY]] -> 101 | F5: =G5+H5+I5 -> 91744 | G5: ='SILK - SOLD'!K107 -> 15636 | H5: ='SILK - PENDING'!H27 -> 0 | I5: ='SILK - ALL'!H189 -> 76108
A6: ALBERTI(ALB) | B6: =E6+D6+C6 -> 186 | C6: ='SILK - SOLD'!C171 -> 59 | D6: ='SILK - PENDING'!D37 -> 1 | E6: ='SILK - ALL'!D321 -> 126 | F6: =G6+H6+I6 -> 111639.87 | G6: ='SILK - SOLD'!K171 -> 34146.6 | H6: ='SILK - PENDING'!H37 -> 693 | I6: ='SILK - ALL'!H321 -> 76800.27
A7: MARITEX (MAR) | B7: =E7+D7+C7 -> 167 | C7: ='SILK - SOLD'!C267 -> 90 | D7: ='SILK - PENDING'!D46 -> 1 | E7: ='SILK - ALL'!D402 -> 76 | F7: =G7+H7+I7 -> 108447.75 | G7: ='SILK - SOLD'!K267 -> 58781 | H7: ='SILK - PENDING'!H46 -> 850 | I7: ='SILK - ALL'!H402 -> 48816.75
A8: NELLA | B8: =E8+D8+C8 -> 50 | C8: ='SILK - SOLD'!C281 -> 7 | D8: ='SILK - PENDING'!D57 -> 2 | E8: ='SILK - ALL'!D448 -> 41 | F8: =G8+H8+I8 -> 34150 | G8: ='SILK - SOLD'!K281 -> 4672 | H8: ='SILK - PENDING'!H57 -> 1400 | I8: ='SILK - ALL'!H448 -> 28078
A9: AVANTGARD (AVAN) | B9: =E9+D9+C9 -> 44 | C9: ='SILK - SOLD'!C300 -> 14 | D9: ='SILK - PENDING'!D65 -> 2 | E9: ='SILK - ALL'!D481 -> 28 | F9: =G9+H9+I9 -> 23225 | G9: ='SILK - SOLD'!K300 -> 7475 | H9: ='SILK - PENDING'!H65 -> 950 | I9: ='SILK - ALL'!H481 -> 14800
A10: CASA DELLO (CASA) | B10: =E10+D10+C10 -> 39 | C10: ='SILK - SOLD'!C330 -> 25 | D10: ='SILK - PENDING'!D75 -> 4 | E10: ='SILK - ALL'!D497 -> 10 | F10: =G10+H10+I10 -> 23382 | G10: ='SILK - SOLD'!K330 -> 15630 | H10: ='SILK - PENDING'!H75 -> 1920 | I10: ='SILK - ALL'!H497 -> 5832
A11: STYLE SILK (STYL) | B11: =E11+D11+C11 -> 46 | C11: ='SILK - SOLD'!C345 -> 9 | D11: ='SILK - PENDING'!D84 -> 4 | E11: =STYL_A[[#Totals],[QUALITY]] -> 33 | F11: =G11+H11+I11 -> 26672.5 | G11: ='SILK - SOLD'!K345 -> 5297.5 | H11: ='SILK - PENDING'!H84 -> 2225 | I11: ='SILK - ALL'!H535 -> 19150
A12: INCOMO (INCO) | B12: =E12+D12+C12 -> 20 | C12: ='SILK - SOLD'!C362 -> 12 | D12: ='SILK - PENDING'!D91 -> 1 | E12: ='SILK - ALL'!D547 -> 7 | F12: =G12+H12+I12 -> 11475 | G12: ='SILK - SOLD'!K362 -> 6675 | H12: ='SILK - PENDING'!H91 -> 500 | I12: ='SILK - ALL'!H547 -> 4300
A13: CARNET (UG) | B13: =E13+D13+C13 -> 26 | C13: ='SILK - SOLD'!C371 -> 3 | D13: ='SILK - PENDING'!D99 -> 0 | E13: =UG_A[[#Totals],[QUALITY]] -> 23 | F13: =G13+H13+I13 -> 20125 | G13: ='SILK - SOLD'!K371 -> 1750 | H13: ='SILK - PENDING'!H99 -> 0 | I13: ='SILK - ALL'!H575 -> 18375
A14: CAVALLI+TGM+ROTARY | B14: =E14+D14+C14 -> 11 | C14: ='SILK - SOLD'!C382 -> 5 | D14: ='SILK - PENDING'!D110 -> 1 | E14: ='SILK - ALL'!D586 -> 5 | F14: =G14+H14+I14 -> 11809 | G14: ='SILK - SOLD'!K382 -> 5128 | H14: ='SILK - PENDING'!H110 -> 880 | I14: ='SILK - ALL'!H586 -> 5801
A15: RUFFO (RUFF) | B15: =E15+D15+C15 -> 28 | C15: ='SILK - SOLD'!C389 -> 2 | D15: ='SILK - PENDING'!D118 -> 0 | E15: =RUFF_A[[#Totals],[QUALITY]] -> 26 | F15: =G15+H15+I15 -> 64450 | G15: ='SILK - SOLD'!K389 -> 5500 | H15: ='SILK - PENDING'!H118 -> 0 | I15: ='SILK - ALL'!H617 -> 58950
A16: SETERIE GR(SETE) | B16: =E16+D16+C16 -> 38 | C16: ='SILK - SOLD'!C400 -> 5 | D16: ='SILK - PENDING'!D125 -> 0 | E16: ='SILK - ALL'!D655 -> 33 | F16: =G16+H16+I16 -> 18345 | G16: ='SILK - SOLD'!K400 -> 3077 | H16: ='SILK - PENDING'!H125 -> 0 | I16: ='SILK - ALL'!H655 -> 15268
A17: TESSILE(TESSI) | B17: =E17+D17+C17 -> 31 | C17: ='SILK - SOLD'!C413 -> 8 | D17: ='SILK - PENDING'!D132 -> 1 | E17: ='SILK - ALL'!D682 -> 22 | F17: =G17+H17+I17 -> 16769.5 | G17: ='SILK - SOLD'!K413 -> 4660.5 | H17: ='SILK - PENDING'!H132 -> 522.5 | I17: ='SILK - ALL'!H682 -> 11586.5
A18: QUORUM(QUO) | B18: =E18+D18+C18 -> 24 | C18: ='SILK - SOLD'!C423 -> 1 | D18: ='SILK - PENDING'!D141 -> 3 | E18: ='SILK - ALL'!D707 -> 20 | F18: =G18+H18+I18 -> 12240 | G18: ='SILK - SOLD'!K423 -> 539 | H18: ='SILK - PENDING'!H141 -> 1650 | I18: ='SILK - ALL'!H707 -> 10051
A19: SILKOMO (SILKO) | B19: =E19+D19+C19 -> 24 | C19: ='SILK - SOLD'!C447 -> 13 | D19: ='SILK - PENDING'!D151 -> 5 | E19: ='SILK - ALL'!D718 -> 6 | F19: =G19+H19+I19 -> 13476 | G19: ='SILK - SOLD'!K447 -> 7590 | H19: ='SILK - PENDING'!H151 -> 2286 | I19: ='SILK - ALL'!H718 -> 3600
A20: NO CODE (NC) | B20: =E20+D20+C20 -> 59 | C20: ='SILK - SOLD'!C473 -> 21 | D20: ='SILK - PENDING'!D171 -> 15 | E20: ='SILK - ALL'!D746 -> 23 | F20: =G20+H20+I20 -> 31105 | G20: ='SILK - SOLD'!K473 -> 10905.5 | H20: ='SILK - PENDING'!H171 -> 8023 | I20: ='SILK - ALL'!H746 -> 12176.5
A22: SILK TOTAL | B22: =SUM(B4:B20) -> 1054 | C22: =SUM(C4:C20) -> 360 | D22: =SUM(D4:D20) -> 44 | E22: =SUM(E4:E20) -> 650 | F22: =G22+H22+I22 -> 699279.62 | G22: =SUM(G4:G20) -> 224661.1 | H22: =SUM(H4:H20) -> 24677.5 | I22: =SUM(I4:I20) -> 449941.02
A24: 2. LACE
A25: PLAIN LACE (PL) | B25: ='LACE - STOCK OVERVIEW'!L3 -> 62 | C25: ='LACE - STOCK OVERVIEW'!F3 -> 16 | D25: ='LACE - STOCK OVERVIEW'!I3 -> 3 | E25: ='LACE - ALL'!C56 -> 43 | F25: =G25+H25+I25 -> 49242.1 | G25: ='LACE - STOCK OVERVIEW'!H3 -> 11238.6 | H25: ='LACE - STOCK OVERVIEW'!K3 -> 2160 | I25: 35843.5
A26: LUREXLACE (LL) | B26: ='LACE - STOCK OVERVIEW'!L4 -> 68 | C26: ='LACE - STOCK OVERVIEW'!F4 -> 17 | D26: ='LACE - STOCK OVERVIEW'!I4 -> 1 | E26: ='LACE - ALL'!C111 -> 50 | F26: =G26+H26+I26 -> 86282.41 | G26: ='LACE - STOCK OVERVIEW'!H4 -> 21860.91 | H26: ='LACE - STOCK OVERVIEW'!K4 -> 1245.5 | I26: 63176
A27: CASA DELLO (CD) | B27: ='LACE - STOCK OVERVIEW'!L5 -> 52 | C27: ='LACE - STOCK OVERVIEW'!F5 -> 18 | D27: ='LACE - STOCK OVERVIEW'!I5 -> 0 | E27: =B27-C27-D27 -> 34 | F27: =G27+H27+I27 -> 43790.08 | G27: ='LACE - STOCK OVERVIEW'!H5 -> 15106.08 | H27: ='LACE - STOCK OVERVIEW'!K5 -> 0 | I27: 28684
A28: LACE TOTAL | B28: =SUM(B25:B27) -> 182 | C28: =SUM(C25:C27) -> 51 | D28: =SUM(D25:D27) -> 4 | E28: =B28-C28-D28 -> 127 | F28: =SUM(F25:F27) -> 179314.59 | G28: =SUM(G25:G27) -> 48205.59 | H28: =SUM(H25:H27) -> 3405.5 | I28: =SUM(I25:I27) -> 127703.5
A30: RICCIARINI CORD LACE (70) | B30: 70 | C30: ='LACE - STOCK OVERVIEW'!F7 -> 0 | D30: ='LACE - STOCK OVERVIEW'!I7 -> 0 | E30: =B30-C30-D30 -> 70 | F30: ='LACE - STOCK OVERVIEW'!E7 -> 9900 | G30: ='LACE - STOCK OVERVIEW'!H7 -> 0 | H30: ='LACE - STOCK OVERVIEW'!K7 -> 0 | I30: ='LACE - STOCK OVERVIEW'!N7 -> 9900
A32: 3. CEMB
A33: CEMB 40 | B33: ='CEMB - STOCK OVERVIEW'!C3 -> 201 | C33: ='CEMB - STOCK OVERVIEW'!D3 -> 6 | D33: ='CEMB - PENDING'!C18 -> 0 | E33: =B33-C33-D33 -> 195 | F33: =G33+H33+I33 -> 30476.25 | G33: =Table121[[#Totals],[COST PER PC]] -> 301 | H33: =Table127[[#Totals],[COST PIECE RM]] -> 0 | I33: 30175.25
A34: CEMB 60 | B34: 81 | C34: ='CEMB - STOCK OVERVIEW'!D4 -> 14 | D34: ='CEMB - PENDING'!C31 -> 0 | E34: =B34-C34-D34 -> 67 | F34: =G34+H34+I34 -> 26940 | G34: =Table126[[#Totals],[COST PER PC]] -> 4440 | H34: =Table130[[#Totals],[COST PIECE RM]] -> 0 | I34: 22500
A35: CEMB 120 | B35: 62 | C35: ='CEMB - STOCK OVERVIEW'!D5 -> 7 | D35: ='CEMB - PENDING'!C43 -> 0 | E35: =B35-C35-D35 -> 55 | F35: =G35+H35+I35 -> 35271.8 | G35: ='CEMB - SOLD'!L56 -> 3975.8 | H35: =Table137[[#Totals],[COST PIECE RM]] -> 0 | I35: 31296
A36: CEMB 180 | B36: 52 | C36: ='CEMB - STOCK OVERVIEW'!D6 -> 5 | D36: ='CEMB - PENDING'!C55 -> 0 | E36: =B36-C36-D36 -> 47 | F36: =G36+H36+I36 -> 53169.75 | G36: ='CEMB - SOLD'!L68 -> 4839.75 | H36: =Table138[[#Totals],[COST PIECE RM]] -> 0 | I36: 48330
A38: LACE (CEMB) TOTAL | B38: =SUM(B33:B36) -> 396 | C38: =SUM(C33:C36) -> 32 | D38: =SUM(D33:D36) -> 0 | E38: =SUM(E33:E36) -> 364 | F38: =SUM(F33:F36) -> 145857.8 | G38: =SUM(G33:G36) -> 13556.55 | H38: =SUM(H33:H36) -> 0 | I38: =SUM(I33:I36) -> 132301.25
A40: 4. BEIRUT
A41: LACE (BEIRUT) | B41: 95 | C41: ='LACE - SOLD'!C100 -> 2 | D41: ='LACE - PENDING'!C50 -> 0 | E41: =B41-C41-D41 -> 93 | F41: =G41+H41+I41 -> 138435 | G41: ='LACE - SOLD'!J100 -> 1920 | H41: ='LACE - PENDING'!G50 -> 0 | I41: 136515
A43: BEIRUT TOTAL | B43: =B41 -> 95 | C43: =C41 -> 2 | D43: =D41 -> 0 | E43: =E41 -> 93 | F43: =F41 -> 138435 | G43: =G41 -> 1920 | H43: =H41 -> 0 | I43: =I41 -> 136515
A45: 5. EMBROIDERY
A46: ARGOMENTI (ARGO) | B46: 10 | C46: 0 | D46: 0 | E46: ='EMBROIDERY - ALL'!D25 -> 10 | F46: 15672.5 | G46: 0 | I46: =F46-G46-H46 -> 15672.5
A47: RICAMIFICIO PAOLO (RIC-P) | B47: 5 | C47: 2 | D47: 0 | E47: ='EMBROIDERY - ALL'!D34 -> 3 | F47: 35185 | G47: 6210 | I47: =F47-G47-H47 -> 28975
A48: HOFERHECHT (HOFE) | B48: 5 | C48: 0 | D48: 0 | E48: ='EMBROIDERY - ALL'!D45 -> 5 | F48: 18920 | G48: 0 | I48: =F48-G48-H48 -> 18920
...

Sheet SILK  - STOCK OVERVIEW
A1: ITEM | B1: TOTAL BOXES | C1: BOXES SOLD | D1: TOTAL BOXES IN OFFICE | E1: BOXES AVAILABLE | F1: BOXES PENDING | G1: TOTAL METERS | H1: TOTAL METERS IN OFFICE | I1: TOTAL METERS IN SOLD | J1: TOTAL METERS PENDING | K1: TOTAL COST VALUE MYR | L1: TOTAL COST VALUE OF SOLD | M1: TOTAL COST VALUE IN OFFICE MYR | N1: TOTAL COST VALUE OF PENDING | O1: NET PROFIT AFTER COST
A2: M&M 1-70
A3: CDC | B3: =C3+F3+E3 -> 69 | C3: =COUNTIFS('SILK - SOLD'!D14:D78,"*CDC*") -> 29 | D3: =F3+E3 -> 40 | E3: =COUNTIF(M7M_A[QUALITY],"*CDC") -> 38 | F3: =COUNTIF('SILK - PENDING'!D13:D17,"*CDC*") -> 2 | G3: =H3+I3+J3 -> 354.1 | H3: =SUMIF(M7M_A[#All],"CDC",'SILK - ALL'!E12:E83) -> 195.2 | I3: =SUMIF('SILK - SOLD'!D13:D79,"CDC",'SILK - SOLD'!E13:E79) -> 147.7 | J3: =SUMIF(MM_P[#All],"CDC",Table6[#All]) -> 11.2 | K3: =L3+N3+M3 -> 46835 | L3: =SUMIF('SILK - SOLD'!D13:D79,"CDC",'SILK - SOLD'!K13:K79) -> 19760.5 | M3: =SUMIF(M7M_A[#All],"CDC",'SILK - ALL'!H12:H82) -> 25506.5 | N3: =SUMIF(MM_P[#All],"CDC",'SILK - PENDING'!H13:H18) -> 1568
A4: GEORGETTE | B4: =C4+F4+E4 -> 66 | C4: =COUNTIFS('SILK - SOLD'!D14:D76,"*GEORGETTE*") -> 32 | D4: =F4+E4 -> 34 | E4: =COUNTIF('SILK - ALL'!D13:D83,"*GEORGETTE*") -> 32 | F4: =COUNTIF('SILK - PENDING'!D13:D17,"*CDC*") -> 2 | G4: =H4+I4+J4 -> 299.2 | H4: =SUMIF(M7M_A[#All],"GEORGETTE*",'SILK - ALL'!E12:E83) -> 142 | I4: =SUMIF('SILK - SOLD'!D13:D79,"GEORGETTE",'SILK - SOLD'!E13:E79) -> 146.2 | J4: =SUMIF(MM_P[#All],"GEORGETTE",Table6[#All]) -> 11 | K4: =L4+N4+M4 -> 31011.5 | L4: =SUMIF('SILK - SOLD'!D13:D79,"GEORGETTE",'SILK - SOLD'!K13:K79) -> 15060 | M4: =SUMIF(M7M_A[#All],"GEORGETTE*",'SILK - ALL'!H12:H82) -> 14741.5 | N4: =SUMIF(MM_P[#All],"GEORGETTE",'SILK - PENDING'!H13:H18) -> 1210
A5: CHIFFON | B5: =C5+F5+E5 -> 3 | C5: =COUNTIFS('SILK - SOLD'!D15:D79,"*CHIFFON*") -> 3 | D5: =F5+E5 -> 0 | E5: =COUNTIF('SILK - ALL'!D13:D84,"*CHIFFON*") -> 0 | F5: =COUNTIF('SILK - PENDING'!D15:D19,"*CHIFFON*") -> 0 | G5: =H5+I5+J5 -> 16 | H5: =SUMIF(M7M_A[#All],"CHIFFON*",'SILK - ALL'!E13:E84) -> 0 | I5: =SUMIF('SILK - SOLD'!D13:D79,"CHIFFON",'SILK - SOLD'!E13:E79) -> 16 | J5: =SUMIF(MM_P[#All],"CHIFFON",Table6[#All]) -> 0 | K5: =L5+N5+M5 -> 1745 | L5: =SUMIF('SILK - SOLD'!D13:D79,"CHIFFON",'SILK - SOLD'!K13:K79) -> 1745 | M5: =SUMIF(M7M_A[#All],"CHIFFON",'SILK - ALL'!H12:H82) -> 0 | N5: =SUMIF(MM_P[#All],"CHIFFON",'SILK - PENDING'!H13:H18) -> 0
A6: SATIN | B6: =C6+F6+E6 -> 1 | C6: =COUNTIFS('SILK - SOLD'!D16:D80,"*SATIN*") -> 1 | D6: =F6+E6 -> 0 | E6: =COUNTIF('SILK - ALL'!D13:D85,"*SATIN*") -> 0 | F6: =COUNTIF('SILK - PENDING'!D15:D19,"*SATIN*") -> 0 | G6: =H6+I6+J6 -> 5.5 | H6: =SUMIF(M7M_A[#All],"SATIN*",'SILK - ALL'!E14:E85) -> 0 | I6: =SUMIF('SILK - SOLD'!D13:D79,"SATIN",'SILK - SOLD'!E13:E79) -> 5.5 | J6: =SUMIF(MM_P[#All],"SATIN",Table6[#All]) -> 0 | K6: =L6+N6+M6 -> 632.5 | L6: =SUMIF('SILK - SOLD'!D13:D79,"*SATIN*",'SILK - SOLD'!K13:K79) -> 632.5 | M6: =SUMIF(M7M_A[#All],"*SATIN*",'SILK - ALL'!H12:H82) -> 0 | N6: =SUMIF(MM_P[#All],"SATIN",'SILK - PENDING'!H13:H18) -> 0
A7: M&M 1-70 TOTAL | B7: =SUM(B3:B6) -> 139 | C7: =SUM(C3:C6) -> 65 | D7: =SUM(D3:D6) -> 74 | E7: =SUM(E3:E6) -> 70 | F7: =SUM(F3:F6) -> 4 | G7: =SUM(G3:G6) -> 674.8 | H7: =SUM(H3:H6) -> 337.2 | I7: =SUM(I3:I6) -> 315.4 | ... N7: =SUM(N3:N6) -> 2778 | O7: ='SILK - SOLD'!L79 -> 41540.2
A9: ARGOMENTI (ARGO)
A10: CDC | B10: =C10+F10+E10 -> 55 | C10: =COUNTIFS('SILK - SOLD'!D85:D107,"*CDC*") -> 14 | D10: =F10+E10 -> 41 | E10: =COUNTIF(ARGO_A[#All],"CDC") -> 41 | F10: =COUNTIF(ARGO_P[#All],"*CDC*") -> 0 | G10: =H10+I10+J10 -> 299.1 | H10: =SUMIF(ARGO_A[#All],"CDC",'SILK - ALL'!E87:E189) -> 224.6 | I10: =SUMIF(ARGO_S[#All],"CDC",ARGO_SO[#All]) -> 74.5 | J10: =SUMIF(ARGO_P[#All],"CDC",Table7[#All]) -> 0 | K10: =M10+L10+N10 -> 42039 | L10: =SUMIF(ARGO_S[#All],"CDC",'SILK - SOLD'!K85:K107) -> 10595 | M10: =SUMIF(ARGO_A[#All],"CDC",'SILK - ALL'!H87:H188) -> 31444 | N10: =SUMIF(ARGO_P[#All],"CDC",Table82[#All]) -> 0
A11: GEORGETTE | B11: =C11+F11+E11 -> 14 | C11: =COUNTIFS('SILK - SOLD'!D85:D107,"*GEORGETTE*") -> 1 | D11: =F11+E11 -> 13 | E11: =COUNTIF(ARGO_A[#All],"GEORGETTE") -> 13 | F11: =COUNTIF(ARGO_P[#All],"*GEORGETTE*") -> 0 | G11: =H11+I11+J11 -> 64 | H11: =SUMIF(ARGO_A[#All],"GEORGETTE",'SILK - ALL'!E87:E189) -> 61.5 | I11: =SUMIF(ARGO_S[#All],"GEORGETTE",ARGO_SO[#All]) -> 2.5 | J11: =SUMIF(ARGO_P[#All],"GEORGETTE",Table7[#All]) -> 0 | K11: =M11+L11+N11 -> 7040 | L11: =SUMIF(ARGO_S[#All],"GEORGETTE",'SILK - SOLD'!K85:K107) -> 275 | M11: =SUMIF(ARGO_A[#All],"GEORGETTE",'SILK - ALL'!H87:H188) -> 6765 | N11: =SUMIF(ARGO_P[#All],"GEORGETTE",Table82[#All]) -> 0
A12: CHIFFON | B12: =C12+F12+E12 -> 10 | C12: =COUNTIFS('SILK - SOLD'!D85:D107,"*CHIFFON*") -> 0 | D12: =F12+E12 -> 10 | E12: =COUNTIF(ARGO_A[#All],"CHIFFON") -> 10 | F12: =COUNTIF(ARGO_P[#All],"*CHIFFON*") -> 0 | G12: =H12+I12+J12 -> 65.5 | H12: =SUMIF(ARGO_A[#All],"CHIFFON",'SILK - ALL'!E87:E189) -> 65.5 | I12: =SUMIF(ARGO_S[#All],"CHIFFON",ARGO_SO[#All]) -> 0 | J12: =SUMIF(ARGO_P[#All],"CHIFFON",Table7[#All]) -> 0 | K12: =M12+L12+N12 -> 7205 | L12: =SUMIF(ARGO_S[#All],"CHIFFON",'SILK - SOLD'!K85:K107) -> 0 | M12: =SUMIF(ARGO_A[#All],"CHIFFON",'SILK - ALL'!H87:H188) -> 7205 | N12: =SUMIF(ARGO_P[#All],"CHIFFON",Table82[#All]) -> 0
A13: LUREX | B13: =C13+F13+E13 -> 35 | C13: =COUNTIFS('SILK - SOLD'!D85:D107,"*LUREX*") -> 4 | D13: =F13+E13 -> 31 | E13: =COUNTIF(ARGO_A[#All],"LUREX") -> 31 | F13: =COUNTIF(ARGO_P[#All],"*LUREX*") -> 0 | G13: =H13+I13+J13 -> 177 | H13: =SUMIF(ARGO_A[#All],"LUREX",'SILK - ALL'!E87:E189) -> 157.2 | I13: =SUMIF(ARGO_S[#All],"LUREX",ARGO_SO[#All]) -> 19.8 | J13: =SUMIF(ARGO_P[#All],"LUREX",Table7[#All]) -> 0 | K13: =M13+L13+N13 -> 30090 | L13: =SUMIF(ARGO_S[#All],"LUREX",'SILK - SOLD'!K85:K107) -> 3366 | M13: =SUMIF(ARGO_A[#All],"LUREX",'SILK - ALL'!H87:H188) -> 26724 | N13: =SUMIF(ARGO_P[#All],"LUREX",Table82[#All]) -> 0
A14: LUREX_CHIFFON | B14: =C14+F14+E14 -> 2 | C14: =COUNTIFS('SILK - SOLD'!D85:D107,"*LUREX_CHIFFON*") -> 0 | D14: =F14+E14 -> 2 | E14: =COUNTIF(ARGO_A[#All],"*LUREX_CHIFFON") -> 2 | F14: =COUNTIF(ARGO_P[#All],"*LUREX_CHIFFON*") -> 0 | G14: =H14+I14+J14 -> 10 | H14: =SUMIF(ARGO_A[#All],"LUREX_CHIFFON",'SILK - ALL'!E87:E189) -> 10 | I14: =SUMIF(ARGO_S[#All],"LUREX_CHIFFON",ARGO_SO[#All]) -> 0 | J14: =SUMIF(ARGO_P[#All],"LUREX_CHIFFON",Table7[#All]) -> 0 | K14: =M14+L14+N14 -> 1100 | L14: =SUMIF(ARGO_S[#All],"LUREX_CHIFFON",'SILK - SOLD'!K85:K107) -> 0 | M14: =SUMIF(ARGO_A[#All],"LUREX_CHIFFON",'SILK - ALL'!H87:H188) -> 1100 | N14: =SUMIF(ARGO_P[#All],"LUREX_CHIFFONC",Table82[#All]) -> 0
A15: SATIN | B15: =C15+F15+E15 -> 4 | C15: =COUNTIFS('SILK - SOLD'!D85:D107,"*SATIN*") -> 1 | D15: =F15+E15 -> 3 | E15: =COUNTIF(ARGO_A[#All],"SATIN") -> 3 | F15: =COUNTIF(ARGO_P[#All],"*SATIN*") -> 0 | G15: =H15+I15+J15 -> 20.5 | H15: =SUMIF(ARGO_A[#All],"SATIN",'SILK - ALL'!E87:E189) -> 15.5 | I15: =SUMIF(ARGO_S[#All],"SATIN",ARGO_SO[#All]) -> 5 | J15: =SUMIF(ARGO_P[#All],"SATIN",Table7[#All]) -> 0 | K15: =M15+L15+N15 -> 2870 | L15: =SUMIF(ARGO_S[#All],"SATIN",'SILK - SOLD'!K85:K107) -> 700 | M15: =SUMIF(ARGO_A[#All],"SATIN",'SILK - ALL'!H87:H188) -> 2170 | N15: =SUMIF(ARGO_P[#All],"SATIN",Table82[#All]) -> 0
A16: JACQUARD | B16: =C16+F16+E16 -> 2 | C16: =COUNTIFS('SILK - SOLD'!D85:D107,"*JACQUARD*") -> 1 | D16: =F16+E16 -> 1 | E16: =COUNTIF(ARGO_A[#All],"*JACQUARD") -> 1 | F16: =COUNTIF(ARGO_P[#All],"*JACQUARD*") -> 0 | G16: =H16+I16+J16 -> 10 | H16: =SUMIF(ARGO_A[#All],"JACQUARD",'SILK - ALL'!E87:E189) -> 5 | I16: =SUMIF(ARGO_S[#All],"JACQUARD",ARGO_SO[#All]) -> 5 | J16: =SUMIF(ARGO_P[#All],"JACQUARD",Table7[#All]) -> 0 | K16: =M16+L16+N16 -> 1400 | L16: =SUMIF(ARGO_S[#All],"*JACQUARD*",'SILK - SOLD'!K85:K107) -> 700 | M16: =SUMIF(ARGO_A[#All],"JACQUARD",'SILK - ALL'!H87:H188) -> 700 | N16: =SUMIF(ARGO_P[#All],"JACQUARD",Table82[#All]) -> 0
A17: ARGOMENTI (ARGO) TOTAL | B17: =SUM(B10:B16) -> 122 | C17: =SUM(C10:C16) -> 21 | D17: =SUM(D10:D16) -> 101 | E17: =SUM(E10:E16) -> 101 | F17: =SUM(F10:F16) -> 0 | G17: =SUM(G10:G16) -> 646.1 | H17: =SUM(H10:H16) -> 539.3 | I17: =SUM(I10:I16) -> 106.8 | ... N17: =SUM(N10:N16) -> 0 | O17: ='SILK - SOLD'!L107 -> 11520
A19: ALBERTI (ALB)
A20: CDC | B20: =C20+F20+E20 -> 80 | C20: =COUNTIFS(Table21[#All],"*CDC*") -> 23 | D20: =F20+E20 -> 57 | E20: =COUNTIF('SILK - ALL'!D195:D320,"*CDC") -> 56 | F20: =COUNTIF(ALB_P[#All],"*CDC*") -> 1 | G20: =H20+I20+J20 -> 440.1 | H20: =SUMIF(ALB_A[#All],"CDC",Table36[#All]) -> 308.9 | I20: =SUMIF(Table21[#All],"CDC",ALB_SO[#All]) -> 124.9 | J20: =SUMIF(ALB_P[#All],"CDC",Table8[#All]) -> 6.3 | K20: =M20+L20+N20 -> 49589.27 | L20: =SUMIF(Table21[#All],"CDC",Table66[#All]) -> 14917 | M20: =SUMIF(ALB_A[#All],"CDC",Table48[#All]) -> 33979.27 | N20: =SUMIF(ALB_P[#All],"CDC",Table83[#All]) -> 693
A21: GEORGETTE | B21: =C21+F21+E21 -> 71 | C21: =COUNTIFS(Table21[#All],"*GEORGETTE*") -> 26 | D21: =F21+E21 -> 45 | E21: =COUNTIF('SILK - ALL'!D195:D320,"*GEORGETTE") -> 45 | F21: =COUNTIF(ALB_P[#All],"*GEORGETTE*") -> 0 | G21: =H21+I21+J21 -> 372.1 | H21: =SUMIF(ALB_A[#All],"GEORGETTE",Table36[#All]) -> 242.3 | I21: =SUMIF(Table21[#All],"GEORGETTE",ALB_SO[#All]) -> 129.8 | J21: =SUMIF(ALB_P[#All],"GEORGETTE",Table8[#All]) -> 0 | K21: =M21+L21+N21 -> 38878 | L21: =SUMIF(Table21[#All],"GEORGETTE",Table66[#All]) -> 12890 | M21: =SUMIF(ALB_A[#All],"GEORGETTE",Table48[#All]) -> 25988 | N21: =SUMIF(ALB_P[#All],"GEORGETTE",Table83[#All]) -> 0
A22: CHIFFON | B22: =C22+F22+E22 -> 5 | C22: =COUNTIFS(Table21[#All],"*CHIFFON*") -> 1 | D22: =F22+E22 -> 4 | E22: =COUNTIF('SILK - ALL'!D195:D320,"*CHIFFON") -> 4 | F22: =COUNTIF(ALB_P[#All],"*CHIFFON*") -> 0 | G22: =H22+I22+J22 -> 28 | H22: =SUMIF(ALB_A[#All],"CHIFFON",Table36[#All]) -> 23 | I22: =SUMIF(Table21[#All],"CHIFFON",ALB_SO[#All]) -> 5 | J22: =SUMIF(ALB_P[#All],"CHIFFON",Table8[#All]) -> 0 | K22: =M22+L22+N22 -> 3080 | L22: =SUMIF(Table21[#All],"CHIFFON",Table66[#All]) -> 550 | M22: =SUMIF(ALB_A[#All],"CHIFFON",Table48[#All]) -> 2530 | N22: =SUMIF(ALB_P[#All],"CHIFFON",Table83[#All]) -> 0
A23: LUREX | B23: =C23+F23+E23 -> 17 | C23: =COUNTIFS(Table21[#All],"*LUREX*") -> 7 | D23: =F23+E23 -> 10 | E23: =COUNTIF('SILK - ALL'!D195:D320,"*LUREX") -> 10 | F23: =COUNTIF(ALB_P[#All],"*LUREX*") -> 0 | G23: =H23+I23+J23 -> 95.6 | H23: =SUMIF(ALB_A[#All],"LUREX",Table36[#All]) -> 58.4 | I23: =SUMIF(Table21[#All],"LUREX",ALB_SO[#All]) -> 37.2 | J23: =SUMIF(ALB_P[#All],"lUREX",Table8[#All]) -> 0 | K23: =M23+L23+N23 -> 12795.6 | L23: =SUMIF(Table21[#All],"LUREX",Table66[#All]) -> 4619.6 | M23: =SUMIF(ALB_A[#All],"LUREX",Table48[#All]) -> 8176 | N23: =SUMIF(ALB_P[#All],"LUREX",Table83[#All]) -> 0
A24: SATIN | B24: =C24+F24+E24 -> 5 | C24: =COUNTIFS(Table21[#All],"*SATIN*") -> 2 | D24: =F24+E24 -> 3 | E24: =COUNTIF('SILK - ALL'!D195:D320,"*SATIN") -> 3 | F24: =COUNTIF(ALB_P[#All],"*SATIN*") -> 0 | G24: =H24+I24+J24 -> 25.7 | H24: =SUMIF(ALB_A[#All],"SATIN",Table36[#All]) -> 15.7 | I24: =SUMIF(Table21[#All],"SATIN",ALB_SO[#All]) -> 10 | J24: =SUMIF(ALB_P[#All],"SATIN",Table8[#All]) -> 0 | K24: =M24+L24+N24 -> 2897 | L24: =SUMIF(Table21[#All],"SATIN",Table66[#All]) -> 1170 | M24: =SUMIF(ALB_A[#All],"SATIN",Table48[#All]) -> 1727 | N24: =SUMIF(ALB_P[#All],"SATIN",Table83[#All]) -> 0
A25: JACQUARD | B25: =C25+F25+E25 -> 4 | C25: =COUNTIFS(Table21[#All],"*JACQUARD*") -> 0 | D25: =F25+E25 -> 4 | E25: =COUNTIF('SILK - ALL'!D195:D320,"*JACQUARD") -> 4 | F25: =COUNTIF(ALB_P[#All],"*JACQUARD*") -> 0 | G25: =H25+I25+J25 -> 20 | H25: =SUMIF(ALB_A[#All],"JACQUARD",Table36[#All]) -> 20 | I25: =SUMIF(Table21[#All],"JACQUARD",ALB_SO[#All]) -> 0 | J25: =SUMIF(ALB_P[#All],"JACQUARD",Table8[#All]) -> 0 | K25: =M25+L25+N25 -> 2200 | L25: =SUMIF(Table21[#All],"JACQUARD",Table66[#All]) -> 0 | M25: =SUMIF(ALB_A[#All],"JACQUARD",Table48[#All]) -> 2200 | N25: =SUMIF(ALB_P[#All],"JACQUARD",Table83[#All]) -> 0
A26: CADY | B26: =C26+F26+E26 -> 4 | C26: =COUNTIFS(Table21[#All],"*CADY*") -> 0 | D26: =F26+E26 -> 4 | E26: =COUNTIF('SILK - ALL'!D195:D320,"*CADY") -> 4 | F26: =COUNTIF(ALB_P[#All],"*CADY*") -> 0 | G26: =H26+I26+J26 -> 20 | H26: =SUMIF(ALB_A[#All],"*CADY",Table36[#All]) -> 20 | I26: =SUMIF(Table21[#All],"*CADY*",ALB_SO[#All]) -> 0 | J26: =SUMIF(ALB_P[#All],"CADY",Table8[#All]) -> 0 | K26: =M26+L26+N26 -> 2200 | L26: =SUMIF(Table21[#All],"*CADY*",Table66[#All]) -> 0 | M26: =SUMIF(ALB_A[#All],"*CADY",Table48[#All]) -> 2200 | N26: =SUMIF(ALB_P[#All],"CADY",Table83[#All]) -> 0
A27: ALBERTI (ALB) TOTAL | B27: =SUM(B19:B26) -> 186 | C27: =SUM(C20:C26) -> 59 | D27: =SUM(D20:D26) -> 127 | E27: =SUM(E19:E26) -> 126 | F27: =SUM(F20:F26) -> 1 | G27: =SUM(G20:G26) -> 1001.5 | H27: =SUM(H20:H26) -> 688.3 | I27: =SUM(I20:I26) -> 306.9 | J27: =SUM(J20:J26) -> 6.3 | K27: =SUM(K20:K26) -> 111639.87 | L27: =SUM(L20:L26) -> 34146.6 | M27: =SUM(M20:M26) -> 76800.27 | N27: =SUM(N20:N26) -> 693 | O27: ='SILK - SOLD'!L171 -> 30188.6
A29: MARITEX (MAR)
A30: CDC | B30: =C30+F30+E30 -> 74 | C30: =COUNTIFS(Table23[#All],"*CDC*") -> 39 | D30: =F30+E30 -> 35 | E30: =COUNTIF(MAR_A[#All],"*CDC") -> 35 | F30: =COUNTIF('SILK - PENDING'!D42:D45,"*CDC*") -> 0 | G30: =H30+I30+J30 -> 370.2 | H30: =SUMIF(MAR_A[#All],"CDC",Table39[#All]) -> 175.2 | I30: =SUMIF(Table23[#All],"CDC",MAR_SO[#All]) -> 195 | J30: =SUMIF(MAR_P[#All],"CDC",Table9[#All]) -> 0 | K30: =M30+L30+N30 -> 42588 | L30: =SUMIF(Table23[#All],"CDC",Table67[#All]) -> 22440 | M30: =SUMIF(MAR_A[#All],"CDC",Table49[#All]) -> 20148 | N30: =SUMIF(MAR_P[#All],"CDC",Table84[#All]) -> 0
A31: GEORGETTE | B31: =C31+F31+E31 -> 10 | C31: =COUNTIFS(Table23[#All],"*GEORGETTE*") -> 2 | D31: =F31+E31 -> 8 | E31: =COUNTIF(MAR_A[#All],"*GEORGETTE") -> 8 | F31: =COUNTIF('SILK - PENDING'!D42:D45,"*GEORGETTE*") -> 0 | G31: =H31+I31+J31 -> 32.7 | H31: =SUMIF(MAR_A[#All],"GEORGETTE",Table39[#All]) -> 24.1 | I31: =SUMIF(Table23[#All],"GEORGETTE",MAR_SO[#All]) -> 8.6 | J31: =SUMIF(MAR_P[#All],"GEORGETTE",Table9[#All]) -> 0 | K31: =M31+L31+N31 -> 2764.75 | L31: =SUMIF(Table23[#All],"GEORGETTE",Table67[#All]) -> 656 | M31: =SUMIF(MAR_A[#All],"GEORGETTE",Table49[#All]) -> 2108.75 | N31: =SUMIF(MAR_P[#All],"GEORGETTE",Table84[#All]) -> 0
A32: CHIFFON | B32: =C32+F32+E32 -> 0 | C32: =COUNTIFS(Table23[#All],"*CHIFFON*") -> 0 | D32: =F32+E32 -> 0 | E32: =COUNTIF(MAR_A[#All],"CHIFFON") -> 0 | F32: =COUNTIF('SILK - PENDING'!D42:D45,"CHIFFON*") -> 0 | G32: =H32+I32+J32 -> 0 | H32: =SUMIF(MAR_A[#All],"CHIFFON",Table39[#All]) -> 0 | I32: =SUMIF(Table23[#All],"CHIFFON",MAR_SO[#All]) -> 0 | J32: =SUMIF(MAR_P[#All],"CHIFFON",Table9[#All]) -> 0 | K32: =M32+L32+N32 -> 0 | L32: =SUMIF(Table23[#All],"CHIFFON",Table67[#All]) -> 0 | M32: =SUMIF(MAR_A[#All],"CHIFFON",Table49[#All]) -> 0 | N32: =SUMIF(MAR_P[#All],"CHIFFON",Table84[#All]) -> 0
A33: LUREX | B33: =C33+F33+E33 -> 78 | C33: =COUNTIFS(Table23[#All],"*LUREX*") -> 47 | D33: =F33+E33 -> 31 | E33: =COUNTIF(MAR_A[#All],"LUREX") -> 30 | F33: =COUNTIF('SILK - PENDING'!D42:D45,"LUREX") -> 1 | G33: =H33+I33+J33 -> 388 | H33: =SUMIF(MAR_A[#All],"LUREX",Table39[#All]) -> 148 | I33: =SUMIF(Table23[#All],"LUREX",MAR_SO[#All]) -> 235 | J33: =SUMIF(MAR_P[#All],"LUREX",Table9[#All]) -> 5 | K33: =M33+L33+N33 -> 61695 | L33: =SUMIF(Table23[#All],"LUREX",Table67[#All]) -> 35685 | M33: =SUMIF(MAR_A[#All],"LUREX",Table49[#All]) -> 25160 | N33: =SUMIF(MAR_P[#All],"LUREX",Table84[#All]) -> 850
A34: LUREX_CHIFFON | B34: =C34+F34+E34 -> 1 | C34: =COUNTIFS(Table23[#All],"*LUREX_CHIFFON*") -> 0 | D34: =F34+E34 -> 1 | E34: =COUNTIF(MAR_A[#All],"*LUREX_CHIFFON") -> 1 | F34: =COUNTIF('SILK - PENDING'!D42:D45,"LUREX_CHIFFON") -> 0 | G34: =H34+I34+J34 -> 5 | H34: =SUMIF(MAR_A[#All],"LUREX_CHIFFON",Table39[#All]) -> 5 | I34: =SUMIF(Table23[#All],"LUREX_CHIFFON",MAR_SO[#All]) -> 0 | J34: =SUMIF(MAR_P[#All],"LUREX_CHIFFON",Table9[#All]) -> 0 | K34: =M34+L34+N34 -> 700 | L34: =SUMIF(Table23[#All],"LUREX_CHIFFON",Table67[#All]) -> 0 | M34: =SUMIF(MAR_A[#All],"LUREX_CHIFFON",Table49[#All]) -> 700 | N34: =SUMIF(MAR_P[#All],"LUREX_CHIFFON",Table84[#All]) -> 0
A35: PRINTED_LACE | B35: =C35+F35+E35 -> 2 | C35: =COUNTIFS(Table23[#All],"*PRINTED_KACE*") -> 0 | D35: =F35+E35 -> 2 | E35: =COUNTIF(MAR_A[#All],"*PRINTED_LACE") -> 2 | F35: =COUNTIF('SILK - PENDING'!D42:D45,"*PRINTED_LACE") -> 0 | G35: =H35+I35+J35 -> 20 | H35: =SUMIF(MAR_A[#All],"PRINTED_LACE",Table39[#All]) -> 10 | I35: =SUMIF(Table23[#All],"PRINTED_LACE",MAR_SO[#All]) -> 10 | J35: =SUMIF(MAR_P[#All],"PRINTED_LACE",Table9[#All]) -> 0 | K35: =M35+L35+N35 -> 700 | L35: =SUMIF(Table23[#All],"PRINTED_LACE",Table67[#All]) -> 0 | M35: =SUMIF(MAR_A[#All],"PRINTED_LACE",Table49[#All]) -> 700 | N35: =SUMIF(MAR_P[#All],"CDC",Table84[#All]) -> 0
A36: MARITEX (MAR) TOTAL | B36: =SUM(B30:B35) -> 165 | C36: =SUM(C30:C35) -> 88 | D36: =SUM(D30:D35) -> 77 | E36: =SUM(E30:E35) -> 76 | F36: =SUM(F30:F35) -> 1 | G36: =SUM(G30:G35) -> 815.9 | H36: =SUM(H30:H35) -> 362.3 | I36: =SUM(I30:I35) -> 448.6 | ... N36: =SUM(N30:N35) -> 850 | O36: ='SILK - SOLD'!L267 -> 40709
A38: NELLA
A39: CDC | B39: =C39+F39+E39 -> 13 | C39: =COUNTIFS(Table25[#All],"*CDC*") -> 3 | D39: =F39+E39 -> 10 | E39: =COUNTIF(NELL_A[#All],"CDC") -> 10 | F39: =COUNTIF(Table4[#All],"CDC") -> 0 | G39: =H39+I39+J39 -> 63.4 | H39: =SUMIF(NELL_A[#All],"CDC",Table52[#All]) -> 48.4 | I39: =SUMIF(Table25[#All],"CDC",NELL_SO[#All]) -> 15 | J39: =SUMIF(Table4[#All],"CDC",Table5[#All]) -> 0 | K39: =M39+L39+N39 -> 8876 | L39: =SUMIF(Table25[#All],"CDC",Table68[#All]) -> 2100 | M39: =SUMIF(NELL_A[#All],"CDC",Table50[#All]) -> 6776 | N39: =SUMIF(Table4[#All],"CDC",Table85[#All]) -> 0
A40: GEORGETTE | B40: =C40+F40+E40 -> 2 | C40: =COUNTIFS(Table25[#All],"*GEORGETTE*") -> 1 | D40: =F40+E40 -> 1 | E40: =COUNTIF(NELL_A[#All],"GEORGETTE") -> 1 | F40: =COUNTIF(Table4[#All],"GEORGETTE") -> 0 | G40: =H40+I40+J40 -> 10 | H40: =SUMIF(NELL_A[#All],"GEORGETTE",Table52[#All]) -> 5 | I40: =SUMIF(Table25[#All],"GEORGETTE",NELL_SO[#All]) -> 5 | J40: =SUMIF(Table4[#All],"GEORGETTE",Table5[#All]) -> 0 | K40: =M40+L40+N40 -> 1000 | L40: =SUMIF(Table25[#All],"GEORGETTE",Table68[#All]) -> 500 | M40: =SUMIF(NELL_A[#All],"GEORGETTE",Table50[#All]) -> 500 | N40: =SUMIF(Table4[#All],"GEORGETTE",Table85[#All]) -> 0
A41: SATIN | B41: =C41+F41+E41 -> 16 | C41: =COUNTIFS(Table25[#All],"*SATIN*") -> 2 | D41: =F41+E41 -> 14 | E41: =COUNTIF(NELL_A[#All],"*SATIN*") -> 13 | F41: =COUNTIF(Table4[#All],"SATIN") -> 1 | G41: =H41+I41+J41 -> 80 | H41: =SUMIF(NELL_A[#All],"*SATIN*",Table52[#All]) -> 65 | I41: =SUMIF(Table25[#All],"SATIN",NELL_SO[#All]) -> 10 | J41: =SUMIF(Table4[#All],"SATIN",Table5[#All]) -> 5 | K41: =M41+L41+N41 -> 11300 | L41: =SUMIF(Table25[#All],"SATIN",Table68[#All]) -> 1400 | M41: =SUMIF(NELL_A[#All],"*SATIN*",Table50[#All]) -> 9200 | N41: =SUMIF(Table4[#All],"SATIN",Table85[#All]) -> 700
A42: LUREX_CHIFFON | B42: =C42+F42+E42 -> 6 | C42: =COUNTIFS(Table25[#All],"*LUREX_CHIFFON*") -> 0 | D42: =F42+E42 -> 6 | E42: =COUNTIF(NELL_A[#All],"LUREX_CHIFFON") -> 6 | F42: =COUNTIF(Table4[#All],"LUREX_CHIFFON") -> 0 | G42: =H42+I42+J42 -> 32.2 | H42: =SUMIF(NELL_A[#All],"LUREX_CHIFFON",Table52[#All]) -> 32.2 | I42: =SUMIF(Table25[#All],"LUREX_CHIFFON",NELL_SO[#All]) -> 0 | J42: =SUMIF(Table4[#All],"LUREX_CHIFFON",Table5[#All]) -> 0 | K42: =M42+L42+N42 -> 5324 | L42: =SUMIF(Table25[#All],"LUREX_CHIFFON",Table68[#All]) -> 0 | M42: =SUMIF(NELL_A[#All],"LUREX_CHIFFON",Table50[#All]) -> 5324 | N42: =SUMIF(Table4[#All],"LUREX_CHIFFON",Table85[#All]) -> 0
A43: CHIFFON | B43: =C43+F43+E43 -> 8 | C43: =COUNTIFS(Table25[#All],"CHIFFON") -> 0 | D43: =F43+E43 -> 8 | E43: =COUNTIF(NELL_A[#All],"CHIFFON") -> 8 | F43: =COUNTIF(Table4[#All],"CHIFFON") -> 0 | G43: =H43+I43+J43 -> 39.5 | H43: =SUMIF(NELL_A[#All],"CHIFFON",Table52[#All]) -> 39.5 | I43: =SUMIF(Table25[#All],"CHIFFON",NELL_SO[#All]) -> 0 | J43: =SUMIF(Table4[#All],"CHIFFON",Table5[#All]) -> 0 | K43: =M43+L43+N43 -> 4150 | L43: =SUMIF(Table25[#All],"CHIFFON",Table68[#All]) -> 0 | M43: =SUMIF(NELL_A[#All],"CHIFFON",Table50[#All]) -> 4150 | N43: =SUMIF(Table4[#All],"CHIFFON",Table85[#All]) -> 0
A44: TWILLCDC | B44: =C44+F44+E44 -> 3 | C44: =COUNTIFS(Table25[#All],"*TWILLCDC*") -> 0 | D44: =F44+E44 -> 3 | E44: =COUNTIF(NELL_A[#All],"TWILLCDC") -> 2 | F44: =COUNTIF(Table4[#All],"TWILLCDC") -> 1 | G44: =H44+I44+J44 -> 15 | H44: =SUMIF(NELL_A[#All],"TWILLCDC",Table52[#All]) -> 10 | I44: =SUMIF(Table25[#All],"TWILLCDC",NELL_SO[#All]) -> 0 | J44: =SUMIF(Table4[#All],"TWILLCDC",Table5[#All]) -> 5 | K44: =M44+L44+N44 -> 2100 | L44: =SUMIF(Table25[#All],"TWILLCDC",Table68[#All]) -> 0 | M44: =SUMIF(NELL_A[#All],"TWILLCDC",Table50[#All]) -> 1400 | N44: =SUMIF(Table4[#All],"TWILLCDC",Table85[#All]) -> 700
...

Sheet SILK - ALL
A1: UPDATED ON | F1: UPDATED BY IBRAHIM
A2: DESCRIPTION 31 OCT 2024 | D2: PIECES | F2: VIP-M | I2: NOTED: SOME LINEATRE (LINEA) NOT LISTED .COZ OF SHORT PIECES
A3: TOTAL | D3: 1058 | F3: Sherry - S | H3: PENDING-P
A4: RESERVED (M-30+30+20) | F4: Angie - A
A5: PENDING OUT OFFICE( C-30,K-4,FK-43) | F5: Fong king - FK | I5: Total Cost | K5: =H83+H189+H321+H402+H448+H481+H497+H535+H547+H575+H586+H617+H655+H682+H707+H718+H746 -> 449941.02
A6: SOLD | F6: Bani -B
A7: AVAILABLE | D7: =D3-(D4+D5+D6) -> 1058 | F7: MR. Cetin- C | I7: TOTAL METERS | K7: =E83+E189+E321+E402+E448+E481+E497+E535+E547+E575+E586+E617+E655+E682+E707+E718+E746+8 -> 3249.3
F8: MS. KLARA-K
A10: AVAILABLE
A11: M&M 1-70
A12: NO | B12: DESIGN | C12: ARTICLE | D12: QUALITY | E12: QTY | F12: COST PER MT EURO | G12: COST PER MT RM | H12: COST PIECE RM | I12: V.I.P PER MT RM | J12: V.I.P PIECE RM | K12: SELLING PER MT RM LESS 50% | L12: SELLING PIECE RM | M12: SOLD TO
A13: 1 | B13: VSS-1A | C13: ALB-103A | D13: CDC | E13: 6.1 | F13: 19 | G13: =F13*5 -> 95 | H13: =G13*E13 -> 579.5 | I13: 720 | J13: =I13*E13 -> 4392 | K13: =I13/2 -> 360 | L13: =K13*E13 -> 2196
A14: 2 | B14: VSS-3A | C14: AVAN-18A | D14: CDC | E14: 5 | F14: 23 | G14: =F14*5 -> 115 | H14: =G14*E14 -> 575 | I14: 720 | J14: =I14*E14 -> 3600 | K14: =I14/2 -> 360 | L14: =K14*E14 -> 1800
A15: 3 | B15: VSS-4A | C15: AVAN-39A | D15: CDC | E15: 5 | F15: 23 | G15: =F15*5 -> 115 | H15: =G15*E15 -> 575 | I15: 720 | J15: =I15*E15 -> 3600 | K15: =I15/2 -> 360 | L15: =K15*E15 -> 1800
A16: 4 | B16: NOO-4B | C16: AVAN-39B | D16: GEORGETTE | E16: 5 | F16: 19 | G16: =F16*5 -> 95 | H16: =G16*E16 -> 475 | I16: 720 | J16: =I16*E16 -> 3600 | K16: =I16/2 -> 360 | L16: =K16*E16 -> 1800
A17: 5 | B17: VSS-5A | C17: AVAN-16 | D17: CDC | E17: 5 | F17: 23 | G17: =F17*5 -> 115 | H17: =G17*E17 -> 575 | I17: 720 | J17: =I17*E17 -> 3600 | K17: =I17/2 -> 360 | L17: =K17*E17 -> 1800
A18: 6 | B18: VSS-6A | C18: AVAN-35A | D18: CDC | E18: 5 | F18: 23 | G18: =F18*5 -> 115 | H18: =G18*E18 -> 575 | I18: 720 | J18: =I18*E18 -> 3600 | K18: =I18/2 -> 360 | L18: =K18*E18 -> 1800
A19: 7 | B19: NOO-6B | C19: AVAN-35B | D19: GEORGETTE | E19: 5 | F19: 19 | G19: =F19*5 -> 95 | H19: =G19*E19 -> 475 | I19: 720 | J19: =I19*E19 -> 3600 | K19: =I19/2 -> 360 | L19: =K19*E19 -> 1800
A20: 8 | B20: VSS-7A | C20: AVAN-24A | D20: CDC | E20: 5 | F20: 23 | G20: =F20*5 -> 115 | H20: =G20*E20 -> 575 | I20: 720 | J20: =I20*E20 -> 3600 | K20: =I20/2 -> 360 | L20: =K20*E20 -> 1800
A21: 9 | B21: NOO-7B | C21: AVAN-24B | D21: GEORGETTE | E21: 5 | F21: 19 | G21: =F21*5 -> 95 | H21: =G21*E21 -> 475 | I21: 720 | J21: =I21*E21 -> 3600 | K21: =I21/2 -> 360 | L21: =K21*E21 -> 1800
A22: 10 | B22: VSS-10A | C22: INCO-24A | D22: CDC | E22: 5 | F22: 23.5 | G22: =F22*5 -> 117.5 | H22: =G22*E22 -> 587.5 | I22: 720 | J22: =I22*E22 -> 3600 | K22: =I22/2 -> 360 | L22: =K22*E22 -> 1800
A23: 11 | B23: VSS-13A | C23: INCO-15A | D23: CDC | E23: 5 | F23: 23.5 | G23: =F23*5 -> 117.5 | H23: =G23*E23 -> 587.5 | I23: 720 | J23: =I23*E23 -> 3600 | K23: =I23/2 -> 360 | L23: =K23*E23 -> 1800
A24: 12 | B24: NOO-13B | C24: INCO-15B | D24: GEORGETTE | E24: 5 | F24: 19.5 | G24: =F24*5 -> 97.5 | H24: =G24*E24 -> 487.5 | I24: 720 | J24: =I24*E24 -> 3600 | K24: =I24/2 -> 360 | L24: =K24*E24 -> 1800
... A82: 70 | B82: NOO-66B | C82: ALB-90B | D82: GEORGETTE | E82: 5 | F82: 22 | G82: =F82*5 -> 110 | H82: =G82*E82 -> 550 | I82: 720 | J82: =I82*E82 -> 3600 | K82: =I82/2 -> 360 | L82: =K82*E82 -> 1800
A83: TOTAL COST | D83: =COUNTA(M7M_A[QUALITY]) -> 70 | E83: =SUM(E13:E82) -> 337.2 | H83: =SUM(H13:H82) -> 40248
A86: ARGOMENTI (ARGO)
A87: NO | B87: DESIGN | C87: ARTICLE | D87: QUALITY | E87: QTY | F87: COST PER MT EURO | G87: COST PER MT RM | H87: COST PIECE RM | I87: V.I.P PER MT RM | J87: V.I.P PIECE RM | K87: SELLING PER MT RM LESS 50% | L87: SELLING PIECE RM | M87: SOLD TO
A88: 71 | B88: DUSS-101A | C88: ARGO-31 | D88: LUREX | E88: 6 | F88: 34 | G88: =F88*5 -> 170 | H88: =E88*G88 -> 1020 | I88: =G88*5 -> 850 | J88: =I88*E88 -> 5100 | K88: =I88/2 -> 425 | L88: =K88*E88 -> 2550
A89: 72 | B89: VVS-101B | C89: ARGO-31A | D89: CDC | E89: 5.5 | F89: 28 | G89: =F89*5 -> 140 | H89: =E89*G89 -> 770 | I89: 720 | J89: =I89*E89 -> 3960 | K89: =I89/2 -> 360 | L89: =K89*E89 -> 1980
A90: 73 | B90: DUSS-102A | C90: ARGO-33 | D90: LUREX | E90: 6 | F90: 34 | G90: =F90*5 -> 170 | H90: =E90*G90 -> 1020 | I90: =G90*5 -> 850 | J90: =I90*E90 -> 5100 | K90: =I90/2 -> 425 | L90: =K90*E90 -> 2550
A91: 74 | B91: DDSS-103A | C91: ARGO-32 | D91: LUREX | E91: 5.5 | F91: 34 | G91: =F91*5 -> 170 | H91: =E91*G91 -> 935 | I91: =G91*5 -> 850 | J91: =I91*E91 -> 4675 | K91: =I91/2 -> 425 | L91: =K91*E91 -> 2337.5
A92: 75 | B92: VVS-103B | C92: ARGO-32A | D92: CDC | E92: 5.5 | F92: 28 | G92: =F92*5 -> 140 | H92: =E92*G92 -> 770 | I92: 720 | J92: =I92*E92 -> 3960 | K92: =I92/2 -> 360 | L92: =K92*E92 -> 1980
A93: 76 | B93: DSSS-104A | C93: ARGO-17 | D93: LUREX | E93: 5 | F93: 34 | G93: =F93*5 -> 170 | H93: =E93*G93 -> 850 | I93: =G93*5 -> 850 | J93: =I93*E93 -> 4250 | K93: =I93/2 -> 425 | L93: =K93*E93 -> 2125
A94: 77 | B94: DUSS-104B | C94: ARGO-17A | D94: CDC | E94: 7 | F94: 28 | G94: =F94*5 -> 140 | H94: =E94*G94 -> 980 | I94: 720 | J94: =I94*E94 -> 5040 | K94: =I94/2 -> 360 | L94: =K94*E94 -> 2520
A95: 78 | B95: DSSS-105A | C95: ARGO-11 | D95: LUREX | E95: 5 | F95: 34 | G95: =F95*5 -> 170 | H95: =E95*G95 -> 850 | I95: =G95*5 -> 850 | J95: =I95*E95 -> 4250 | K95: =I95/2 -> 425 | L95: =K95*E95 -> 2125
A96: 79 | B96: DUSS-105B | C96: ARGO-11A | D96: CDC | E96: 7.5 | F96: 28 | G96: =F96*5 -> 140 | H96: =E96*G96 -> 1050 | I96: 720 | J96: =I96*E96 -> 5400 | K96: =I96/2 -> 360 | L96: =K96*E96 -> 2700
A97: 80 | B97: DSSS-106A | C97: ARGO-16 | D97: LUREX | E97: 5 | F97: 34 | G97: =F97*5 -> 170 | H97: =E97*G97 -> 850 | I97: =G97*5 -> 850 | J97: =I97*E97 -> 4250 | K97: =I97/2 -> 425 | L97: =K97*E97 -> 2125
A98: 81 | B98: VVS-106B | C98: ARGO-16A | D98: CDC | E98: 5.5 | F98: 28 | G98: =F98*5 -> 140 | H98: =E98*G98 -> 770 | I98: 720 | J98: =I98*E98 -> 3960 | K98: =I98/2 -> 360 | L98: =K98*E98 -> 1980
A99: 82 | B99: DSSS-107A | C99: ARGO-12 | D99: CDC | E99: 5 | F99: 28 | G99: =F99*5 -> 140 | H99: =E99*G99 -> 700 | I99: 720 | J99: =I99*E99 -> 3600 | K99: =I99/2 -> 360 | L99: =K99*E99 -> 1800
A100: 83 | B100: ENS-107B | C100: ARGO-12A | D100: CDC | E100: 6 | F100: 28 | G100: =F100*5 -> 140 | H100: =E100*G100 -> 840 | I100: 720 | J100: =I100*E100 -> 4320 | K100: =I100/2 -> 360 | L100: =K100*E100 -> 2160
...

Sheet SILK - SOLD
A1: UPDATED ON | F1: UPDATED BY IBRAHIM
A2: DESCRIPTION 31 OCT 2024 | D2: PIECES | F2: VIP-M | I2: NOTED: SOME LINEATRE (LINEA) NOT LISTED .COZ OF SHORT PIECES
A3: TOTAL | D3: 1054 | F3: Sherry - S | H3: PENDING-P
A4: RESERVED (M-30+20) | D4: 50 | F4: Angie - A | I4: Total Cost | K4: =K79+K107+K171+K267+K281+K300+K330+K345+K362+K371+K382+K389+K400+K413+K423+K447+K473 -> 224661.1
A5: PENDING OUT OFFICE( C-30,K-4,S-9) | D5: =30+4+9 -> 43 | F5: Fong king - FK | I5: NET PROFIT | K5: =L79+L107+L171+L267+L281+L300+L330+L345+L362+L371+L382+L389+L400+L413+L423+L447+L473 -> 210978.91
A6: SOLD | D6: =C79+C107+C171+C267+C281+C300+C330+C345+C362+C371+C382+C389+C400+C413+C423+C447+C473 -> 360 | F6: Bani -B
A7: AVAILABLE | D7: =D3-(D4+D5+D6) -> 601 | F7: MR. Cetin- C
F8: MS. KLARA-K
A11: M&M 1-70
A12: SOLD
A13: NO | B13: DESIGN | C13: ARTICLE | D13: QUALITY | E13: QTY | F13: PRICE PER MT | G13: PRICE PER PIECE | H13: NET PRICE AFTER DISCOUNT | I13: COM % | J13: LESS COMMISSION PER PC | K13: COST PER PC | L13: NET PROFIT PER PC | M13: SOLD TO
A14: 1 | B14: VSS-22A | C14: STYL-16A | D14: CDC | E14: 5 | F14: 720 | G14: =F14*E14 -> 3600 | H14: 1800 | I14: 0.2 | J14: =H14*(1-I14) -> 1440 | K14: 700 | L14: 560 | M14: M
A15: 2 | B15: NOO-22B | C15: STYL-16B | D15: GEORGETTE | E15: 5 | F15: 720 | G15: =F15*E15 -> 3600 | H15: 1800 | I15: 0.2 | J15: =H15*(1-I15) -> 1440 | K15: 500 | L15: 760 | M15: M
A16: 3 | B16: VSS-23A | C16: STYL-1A | D16: CDC | E16: 5 | F16: 720 | G16: =F16*E16 -> 3600 | H16: 1800 | I16: 0.2 | J16: =H16*(1-I16) -> 1440 | K16: 700 | L16: 560 | M16: M
A17: 4 | B17: NOO-23B | C17: STYL-1B | D17: GEORGETTE | E17: 5 | F17: 720 | G17: =F17*E17 -> 3600 | H17: 1800 | I17: 0.2 | J17: =H17*(1-I17) -> 1440 | K17: 500 | L17: 760 | M17: M
A18: 5 | B18: VSS-27A | C18: STYL-13A | D18: CDC | E18: 5 | F18: 720 | G18: =F18*E18 -> 3600 | H18: 1800 | I18: 0.2 | J18: =H18*(1-I18) -> 1440 | K18: 700 | L18: 560 | M18: M
A19: 6 | B19: NOO-27B | C19: STYL-13B | D19: GEORGETTE | E19: 5 | F19: 720 | G19: =F19*E19 -> 3600 | H19: 1800 | I19: 0.2 | J19: =H19*(1-I19) -> 1440 | K19: 500 | L19: 760 | M19: M
A20: 7 | B20: VSS-28A | C20: STYL-33A | D20: CDC | E20: 5 | F20: 720 | G20: =F20*E20 -> 3600 | H20: 1800 | I20: 0.2 | J20: =H20*(1-I20) -> 1440 | K20: 700 | L20: 560 | M20: M
A21: 8 | B21: RUG-28B | C21: STYL-33B | D21: GEORGETTE | E21: 2.7 | F21: 720 | G21: =F21*E21 -> 1944 | H21: 972 | I21: 0.2 | J21: =H21*(1-I21) -> 777.6 | K21: 270 | L21: 410.4 | M21: M
A22: 9 | B22: VSS-29A | C22: STYL-35A | D22: CDC | E22: 5 | F22: 720 | G22: =F22*E22 -> 3600 | H22: 1800 | I22: 0.2 | J22: =H22*(1-I22) -> 1440 | K22: 700 | L22: 560 | M22: M
A23: 10 | B23: RUG-29B | C23: STYL-35B | D23: GEORGETTE | E23: 2.7 | F23: 720 | G23: =F23*E23 -> 1944 | H23: 972 | I23: 0.2 | J23: =H23*(1-I23) -> 777.6 | K23: 270 | L23: 410.4 | M23: M
A24: 11 | B24: VSS-24A | C24: STYL-5A | D24: CDC | E24: 5 | F24: 720 | G24: 3600 | H24: 1800 | I24: 0.2 | J24: =H24*(1-I24) -> 1440 | K24: 700 | L24: 560 | M24: M
A25: 12 | B25: RUG-24B | C25: STYL-5B | D25: GEORGETTE | E25: 2.7 | F25: 720 | G25: 1944 | H25: 972 | I25: 0.2 | J25: =H25*(1-I25) -> 777.6 | K25: 270 | L25: 410.4 | M25: M
A26: 13 | B26: VSS-2A | C26: AVAN-32A | D26: CDC | E26: 5 | F26: 720 | G26: 3600 | H26: 1800 | I26: 0.2 | J26: =H26*(1-I26) -> 1440 | K26: 700 | L26: 560 | M26: M
A27: 14 | B27: NOO-2B | C27: AVAN-32B | D27: GEORGETTE | E27: 5 | F27: 720 | G27: 3600 | H27: 1800 | I27: 0.2 | J27: =H27*(1-I27) -> 1440 | K27: 500 | L27: 760 | M27: M
A28: 15 | B28: VSS-8A | C28: AVAN-33A | D28: CDC | E28: 5 | F28: 720 | G28: 3600 | H28: 1800 | I28: 0.2 | J28: =H28*(1-I28) -> 1440 | K28: 700 | L28: 560 | M28: M
A29: 16 | B29: NOO-8B | C29: AVAN-33B | D29: CHIFFON | E29: 5 | F29: 720 | G29: 3600 | H29: 1800 | I29: 0.2 | J29: =H29*(1-I29) -> 1440 | K29: 700 | L29: 560 | M29: M
A30: 17 | B30: VSS-11A | C30: INCO-17A | D30: CDC | E30: 5 | F30: 720 | G30: 3600 | H30: 1800 | I30: 0.2 | J30: =H30*(1-I30) -> 1440 | K30: 587.5 | L30: 672.5 | M30: M
A31: 18 | B31: NOO-11B | C31: INCO-17B | D31: GEORGETTE | E31: 5 | F31: 720 | G31: 3600 | H31: 1800 | I31: 0.2 | J31: =H31*(1-I31) -> 1440 | K31: 487.5 | L31: 772.5 | M31: M
A32: 19 | B32: VSS-14A | C32: INCO-7A | D32: CDC | E32: 5 | F32: 720 | G32: 3600 | H32: 1800 | I32: 0.2 | J32: =H32*(1-I32) -> 1440 | K32: 587.5 | L32: 672.5 | M32: M
A33: 20 | B33: NOO-14B | C33: INCO-7B | D33: GEORGETTE | E33: 5 | F33: 720 | G33: 3600 | H33: 1800 | I33: 0.2 | J33: =H33*(1-I33) -> 1440 | K33: 487.5 | L33: 772.5 | M33: M
A34: 21 | B34: VSS-18A | C34: INCO-11A | D34: CDC | E34: 5 | F34: 720 | G34: 3600 | H34: 1800 | I34: 0.2 | J34: =H34*(1-I34) -> 1440 | K34: 587.5 | L34: 672.5 | M34: M
A35: 22 | B35: VSS-21A | C35: INCO-8A | D35: CDC | E35: 5 | F35: 720 | G35: 3600 | H35: 1800 | I35: 0.2 | J35: =H35*(1-I35) -> 1440 | K35: 587.5 | L35: 852.5 | M35: M
... A63: 50 | B63: NOO-9B | C63: AVAN-38B | D63: CHIFFON | E63: 5 | F63: 720 | G63: 3600 | H63: 1800 | I63: 0.15 | J63: =H63*(1-I63) -> 1530 | K63: 475 | L63: 1055 | M63: M
A64: 51 | B64: VSS-47 A | C64: MAR-118 A | D64: CDC | E64: 5 | F64: 720 | G64: 3600 | H64: 1800 | I64: 0.2 | J64: 1440 | K64: 700 | L64: 740 | M64: M
A65: 52 | B65: RUG-47 B | C65: MAR-118 B | D65: GEORGETTE | E65: 2.7 | F65: 720 | G65: 1944 | H65: 972 | I65: 0.2 | J65: 777.6 | K65: 297 | L65: 480.6 | M65: M
A66: 53 | B66: VVS-67A | C66: ALB-20A | D66: CDC | E66: 5.5 | F66: 720 | G66: 3960 | H66: 1980 | I66: 0.2 | J66: 1584 | K66: 770 | L66: 814 | M66: M
A67: 54 | B67: NOO-67B | C67: ALB-20B | D67: GEORGETTE | E67: 5 | F67: 720 | G67: 3600 | H67: 1800 | I67: 0.2 | J67: 1440 | K67: 550 | L67: 890 | M67: M
A68: 55 | B68: VVS-57A | C68: ALB-12A | D68: CDC | E68: 5.5 | F68: 720 | G68: 3960 | H68: 1980 | I68: 0.2 | J68: 1584 | K68: 770 | L68: 814 | M68: M
A69: 56 | B69: NOO-32B | C69: QUORUM-154B | D69: GEORGETTE | E69: 4.9 | F69: 220 | G69: 1078 | H69: 862.4 | I69: 0 | J69: 862.4 | K69: 539 | L69: 323.4 | M69: FK
...

Sheet SILK - PENDING
B1: UPDATED BY IBRAHIM
B2: VIP-M
B3: Sherry - S | D3: PENDING-P | J3: Total Cost | L3: =H18+H27+H37+H46+H57+H65+H75+H84+H91+H99+H110+H118+H125+H132+H141+H151+H171 -> 24677.5
B4: Angie - A
B5: Fong king - FK | D5: MS. KLARA-K
B6: Bani -B
B7: MR. Cetin- C
A11: PENDING
A12: M&M 1-70
A13: NO | B13: DESIGN | C13: ARTICLE | D13: QUALITY | E13: QTY | F13: COST PER MT EURO | G13: COST PER MT RM | H13: COST PIECE RM | I13: V.I.P PER MT RM | J13: V.I.P PIECE RM | K13: SELLING PER MT RM LESS 50% | L13: SELLING PIECE RM | M13: SOLD TO
A14: 1 | B14: EDS-68A | C14: ALB-110A | D14: CDC | E14: 5.7 | F14: 28 | G14: =F14*5 -> 140 | H14: =G14*E14 -> 798 | I14: 720 | J14: =I14*E14 -> 4104 | K14: =I14/2 -> 360 | L14: =K14*E14 -> 2052 | M14: P-C
A15: 2 | B15: NOO-68B | C15: ALB-110B | D15: GEORGETTE | E15: 5 | F15: 22 | G15: =F15*5 -> 110 | H15: =G15*E15 -> 550 | I15: 720 | J15: =I15*E15 -> 3600 | K15: =I15/2 -> 360 | L15: =K15*E15 -> 1800 | M15: P-C
A16: 3 | B16: DDSS-70A | C16: ALB-122A | D16: CDC | E16: 5.5 | F16: 28 | G16: =F16*5 -> 140 | H16: =G16*E16 -> 770 | I16: 720 | J16: =I16*E16 -> 3960 | K16: =I16/2 -> 360 | L16: =K16*E16 -> 1980 | M16: P-C
A17: 4 | B17: IUS-70B | C17: ALB-122B | D17: GEORGETTE | E17: 6 | F17: 22 | G17: =F17*5 -> 110 | H17: =G17*E17 -> 660 | I17: 720 | J17: =I17*E17 -> 4320 | K17: =I17/2 -> 360 | L17: =K17*E17 -> 2160 | M17: P-C
A18: TOTAL COST | D18: =COUNTA(D14:D17) -> 4 | E18: =SUM(E14:E17) -> 22.2 | H18: =SUM(H14:H17) -> 2778
A21: ARGOMENTI (ARGO)
A22: NO | B22: NO | C22: ARTICLE | D22: QUALITY | E22: QTY | F22: COST PER MT EURO | G22: COST PER MT RM | H22: COST PIECE RM | I22: V.I.P PER MT RM | J22: V.I.P PIECE RM | K22: SELLING PER MT RM LESS 50% | L22: SELLING PIECE RM | M22: SOLD TO
A27: TOTAL COST | D27: =COUNTA(D23:D26) -> 0 | E27: =SUM(E22:E25) -> 0 | H27: =SUM(H22:H26) -> 0
A31: ALBERTI(ALB)
A32: NO | B32: DESIGN | C32: ARTICLE | D32: QUALITY | E32: QTY | F32: COST PER MT EURO | G32: COST PER MT RM | H32: COST PIECE RM | I32: V.I.P PER MT RM | J32: V.I.P PIECE RM | K32: SELLING PER MT RM LESS 50% | L32: SELLING PIECE RM | M32: SOLD TO
A33: 5 | B33: DSSS-257S | C33: ALB-50A | D33: CDC | E33: 6.3 | F33: €22.00 | G33: =F33*5 -> 110 | H33: =G33*E33 -> 693 | I33: 720 | J33: =I33*E33 -> 4536 | K33: =I33/2 -> 360 | L33: =K33*E33 -> 2268 | M33: S
A37: TOTAL COST | D37: =COUNTA(D33:D36) -> 1 | E37: =SUM(E32:E35) -> 6.3 | H37: =SUM(H32:H35) -> 693
A41: MARITEX (MAR)
A42: NO | B42: DESIGN | C42: ARTICLE | D42: QUALITY | E42: QTY | F42: COST PER MT EURO | G42: COST PER MT RM | H42: COST PIECE RM | I42: V.I.P PER MT RM | J42: V.I.P PIECE RM | K42: SELLING PER MT RM | L42: SELLING PIECE RM | M42: SOLD TO
A43: 6 | B43: DSSS-451A | C43: MAR-86 | D43: LUREX | E43: 5 | F43: 34 | G43: =F43*5 -> 170 | H43: =G43*E43 -> 850 | I43: 720 | J43: =I43*E43 -> 3600 | K43: =I43/2 -> 360 | L43: =K43*E43 -> 1800 | M43: S
A46: TOTAL COST | D46: =COUNTA(D43:D45) -> 1 | E46: =SUM(E43:E45) -> 5 | H46: =SUM(H43:H45) -> 850
A50: NELLA
A51: NO | B51: DESIGN | C51: ARTICLE | D51: QUALITY | E51: QTY | F51: COST PER MT EURO | G51: COST PER MT RM | H51: COST PIECE RM | I51: V.I.P PER MT RM | J51: V.I.P PIECE RM | K51: SELLING PER MT RM LESS 50% | L51: SELLING PIECE RM | M51: SOLD TO
A52: 7 | B52: VSS-745 | C52: NELLA-045 | D52: TWILLCDC | E52: 5 | F52: 28 | G52: =F52*5 -> 140 | H52: =G52*E52 -> 700 | I52: 720 | J52: =I52*E52 -> 3600 | K52: =I52/2 -> 360 | L52: =K52*E52 -> 1800 | M52: P-K
A53: 8 | B53: VSS-721 | C53: NELLA-193S | D53: SATIN | E53: 5 | F53: 28 | G53: =F53*5 -> 140 | H53: =G53*E53 -> 700 | I53: 720 | J53: =I53*E53 -> 3600 | K53: =I53/2 -> 360 | L53: =K53*E53 -> 1800 | M53: S
A57: TOTAL COST | D57: =COUNTA(D52:D56) -> 2 | E57: =SUM(E52:E56) -> 10 | H57: =SUM(H52:H56) -> 1400
A60: AVANTGARD (AVAN)
A61: NO | B61: DESIGN | C61: ARTICLE | D61: QUALITY | E61: QTY | F61: COST PER MT EURO | G61: COST PER MT RM | H61: COST PIECE RM | I61: V.I.P PER MT RM | J61: V.I.P PIECE RM | K61: SELLING PER MT RM LESS 50% | L61: SELLING PIECE RM | M61: SOLD TO
A62: 9 | B62: NSS-827 | C62: AVAN-103 | D62: GEORGETTE | E62: 5 | F62: 19 | G62: =F62*5 -> 95 | H62: =E62*G62 -> 475 | I62: 720 | J62: =I62*E62 -> 3600 | K62: =I62/2 -> 360 | L62: =K62*E62 -> 1800 | M62: P-C
A63: 10 | B63: NSS-830 | C63: AVAN-001 | D63: GEORGETTE | E63: 5 | F63: 19 | G63: =F63*5 -> 95 | H63: =E63*G63 -> 475 | I63: 720 | J63: =I63*E63 -> 3600 | K63: =I63/2 -> 360 | L63: =K63*E63 -> 1800 | M63: P-C
A65: TOTAL COST | D65: =COUNTA(D62:D64) -> 2 | E65: =SUM(E62:E64) -> 10 | H65: =SUM(H62:H64) -> 950
A69: CASA DELLO (CASA)
A70: NO | B70: DESIGN | C70: ARTICLE | D70: QUALITY | E70: QTY | F70: COST PER MT EURO | G70: COST PER MT RM | H70: COST PIECE RM | I70: V.I.P PER MT RM | J70: V.I.P PIECE RM | K70: SELLING PER MT RM LESS 50% | L70: SELLING PIECE RM | M70: SOLD TO
A71: 11 | B71: VSS-869 | C71: CASA-57 | D71: CDC | E71: 5 | F71: 24 | G71: =F71*5 -> 120 | H71: =G71*E71 -> 600 | I71: 720 | J71: =I71*E71 -> 3600 | K71: =I71/2 -> 360 | L71: =K71*E71 -> 1800 | M71: P-C
A72: 12 | B72: ASS-876 | C72: CASA-91 A | D72: CDC | E72: 3 | F72: 24 | G72: =F72*5 -> 120 | H72: =G72*E72 -> 360 | I72: 720 | J72: =I72*E72 -> 2160 | K72: =I72/2 -> 360 | L72: =K72*E72 -> 1080 | M72: P-C
...

Sheet LACE  - STOCK OVERVIEW
A1: ITEM | B1: BOXES AVAILABLE | C1: TOTAL BOXES IN OFFICE | D1: TOTAL METERS IN OFFICE | E1: TOTAL VALUE IN OFFICE MYR | F1: BOXES SOLD | G1: TOTAL METERS IN SOLD | H1: TOTAL COST VALUE OF SOLD | I1: BOXES PENDING | J1: TOTAL METERS PENDING | K1: TOTAL VALUE OF PENDING | L1: TOTAL BOXES | M1: TOTAL METERS | N1: TOTAL VALUE MYR | O1: NET PROFIT
A2: LACE
A3: PLAIN LACE (PL) | B3: =PL[[#Totals],[ARTICLE ]] -> 43 | C3: =I3+B3 -> 46 | D3: ='LACE - ALL'!E56 -> 213.1 | E3: ='LACE - ALL'!H56 -> 33683.5 | F3: ='LACE - SOLD'!C32 -> 16 | G3: ='LACE - SOLD'!E32 -> 78.3 | H3: ='LACE - SOLD'!J32 -> 11238.6 | I3: ='LACE - PENDING'!C18 -> 3 | J3: ='LACE - PENDING'!E18 -> 14.4 | K3: ='LACE - PENDING'!G18 -> 2160 | L3: =F3+I3+B3 -> 62 | M3: =D3+G3+J3 -> 305.8 | N3: =H3+K3+E3 -> 47082.1 | O3: ='LACE - SOLD'!L32 -> 14349.68
A4: LUREXLACE (LL) | B4: ='LACE - ALL'!C111 -> 50 | C4: =I4+B4 -> 51 | D4: ='LACE - ALL'!E111 -> 238.4 | E4: ='LACE - ALL'!H111 -> 63176 | F4: ='LACE - SOLD'!C56 -> 17 | G4: ='LACE - SOLD'!E56 -> 82.2 | H4: ='LACE - SOLD'!J56 -> 21860.91 | I4: ='LACE - PENDING'!C30 -> 1 | J4: ='LACE - PENDING'!E30 -> 4.7 | K4: ='LACE - PENDING'!G30 -> 1245.5 | L4: =F4+I4+B4 -> 68 | M4: =D4+G4+J4 -> 325.3 | N4: =H4+K4+E4 -> 86282.41 | O4: ='LACE - SOLD'!L56 -> 26736.891
A5: CASA DELLO (CD) | B5: =CD[[#Totals],[ARTICLE ]] -> 34 | C5: =I5+B5 -> 34 | D5: ='LACE - ALL'!E151 -> 156.8 | E5: ='LACE - ALL'!H151 -> 28684 | F5: ='LACE - SOLD'!C91 -> 18 | G5: ='LACE - SOLD'!E91 -> 93 | H5: ='LACE - SOLD'!J91 -> 15106.08 | I5: ='LACE - PENDING'!C40 -> 0 | J5: ='LACE - PENDING'!E40 -> 0 | K5: ='LACE - PENDING'!G40 -> 0 | L5: =F5+I5+B5 -> 52 | M5: =D5+G5+J5 -> 249.8 | N5: =H5+K5+E5 -> 43790.08 | O5: ='LACE - SOLD'!L91 -> 30607.227
A6: LACE (BEIRUT) | B6: ='LACE - ALL'!B252 -> 93 | C6: =I6+B6 -> 93 | D6: ='LACE - ALL'!E252 -> 591.2 | E6: ='LACE - ALL'!H252 -> 135555 | F6: ='LACE - SOLD'!C100 -> 2 | G6: ='LACE - SOLD'!E100 -> 12.8 | H6: ='LACE - SOLD'!J100 -> 1920 | I6: ='LACE - PENDING'!C50 -> 0 | J6: ='LACE - PENDING'!E50 -> 0 | K6: ='LACE - PENDING'!G50 -> 0 | L6: =F6+I6+B6 -> 95 | M6: =D6+G6+J6 -> 604 | N6: =H6+K6+E6 -> 137475 | O6: ='LACE - SOLD'!L100 -> 120
A7: RICCIARINI CORD LACE (70) | B7: ='LACE - ALL'!B329 -> 70 | C7: =I7+B7 -> 70 | D7: ='LACE - ALL'!E329 -> 330 | E7: ='LACE - ALL'!H329 -> 9900 | F7: ='LACE - SOLD'!C109 -> 0 | G7: ='LACE - SOLD'!E109 -> 0 | H7: ='LACE - SOLD'!J109 -> 0 | I7: ='LACE - PENDING'!C61 -> 0 | J7: ='LACE - PENDING'!E61 -> 0 | K7: ='LACE - PENDING'!G61 -> 0 | L7: =F7+I7+B7 -> 70 | M7: =D7+G7+J7 -> 330 | N7: =H7+K7+E7 -> 9900 | O7: ='LACE - SOLD'!L109 -> 0
A8: LACE TOTAL | B8: =SUM(B3:B7) -> 290 | C8: =SUM(C3:C7) -> 294 | D8: =SUM(D3:D7) -> 1529.5 | E8: =SUM(E3:E7) -> 270998.5 | F8: =SUM(F3:F7) -> 53 | G8: =SUM(G3:G7) -> 266.3 | H8: =SUM(H3:H7) -> 50125.59 | I8: =SUM(I3:I7) -> 4 | ... O8: =SUM(O3:O7) -> 71813.798

Sheet LACE - ALL
A1: UPDATED ON | F1: UPDATED BY IBRAHIM
A2: DESCRIPTION 31 OCT 2024 | D2: PIECES | F2: VIP-M | I2: NOTED: SOME LINEATRE (LINEA) NOT LISTED .COZ OF SHORT PIECES
F3: Sherry - S | H3: PENDING-P
F4: Angie - A
F5: Fong king - FK
F6: Bani -B
F7: MR. Cetin- C | I7: Total Cost | K7: =H56+H111+H151+H252+H329 -> 270998.5
F8: MS. KLARA-K
A11: LAGATOLA PLAN LACE (P.L)
A12: NO | B12: DESIGN | C12: ARTICLE | D12: QUALITY | E12: QTY (m) | F12: COST PER MT EURO | G12: COST PER MT RM | H12: COST PIECE RM | I12: V.I.P PER MT RM | J12: V.I.P PIECE RM | K12: SELLING PER MT RM | L12: SELLING PIECE RM | M12: SOLD TO
A13: 1 | B13: SOL-PL-EAS-2 | C13: ML 007314-090-0 | D13: BONIFICO | E13: 5.3 | F13: 30 | G13: =F13*5 -> 150 | H13: =G13*E13 -> 795 | I13: 918 | J13: =I13*E13 -> 4865.4 | K13: =I13/2 -> 459 | L13: =K13*E13 -> 2432.7
A14: 2 | B14: SOL-PL-ESS-4 | C14: ML 007314-090-0 | D14: BONIFICO | E14: 4.8 | F14: 30 | G14: =F14*5 -> 150 | H14: =G14*E14 -> 720 | I14: 918 | J14: =I14*E14 -> 4406.4 | K14: =I14/2 -> 459 | L14: =K14*E14 -> 2203.2
A15: 3 | B15: SOL-PL-ESS-6 | C15: ML 007314-090-0 | D15: BALZATO | E15: 5 | F15: 30 | G15: =F15*5 -> 150 | H15: =G15*E15 -> 750 | I15: 918 | J15: =I15*E15 -> 4590 | K15: =I15/2 -> 459 | L15: =K15*E15 -> 2295
A16: 4 | B16: SOL-PL-ESS-8 | C16: ML 007314-090-0 | D16: BLUE | E16: 5 | F16: 30 | G16: =F16*5 -> 150 | H16: =G16*E16 -> 750 | I16: 918 | J16: =I16*E16 -> 4590 | K16: =I16/2 -> 459 | L16: =K16*E16 -> 2295
A17: 5 | B17: SOL-PL-DDSS-9 | C17: ML 007314-090-0 | D17: RED | E17: 5.9 | F17: 30 | G17: =F17*5 -> 150 | H17: =G17*E17 -> 885 | I17: 918 | J17: =I17*E17 -> 5416.2 | K17: =I17/2 -> 459 | L17: =K17*E17 -> 2708.1
A18: 6 | B18: SOL-PL-EAS-10 | C18: ML 007314-090-0 | D18: BONIFICO | E18: 5.2 | F18: 30 | G18: =F18*5 -> 150 | H18: =G18*E18 -> 780 | I18: 918 | J18: =I18*E18 -> 4773.6 | K18: =I18/2 -> 459 | L18: =K18*E18 -> 2386.8
A19: 7 | B19: SOL-PL-DSSS-13 | C19: ML 007314-090-0 | D19: BONIFICO | E19: 5.4 | F19: 30 | G19: =F19*5 -> 150 | H19: =G19*E19 -> 810 | I19: 918 | J19: =I19*E19 -> 4957.2 | K19: =I19/2 -> 459 | L19: =K19*E19 -> 2478.6
A20: 8 | B20: SOL-PL-EAS-14 | C20: ML 007314-090-0 | D20: PIENO | E20: 5.2 | F20: 30 | G20: =F20*5 -> 150 | H20: =G20*E20 -> 780 | I20: 918 | J20: =I20*E20 -> 4773.6 | K20: =I20/2 -> 459 | L20: =K20*E20 -> 2386.8
A21: 9 | B21: SOL-PL-VSS-18 | C21: ML 007314-090-0 | D21: BONIFICO | E21: 4.3 | F21: 30 | G21: =F21*5 -> 150 | H21: =G21*E21 -> 645 | I21: 918 | J21: =I21*E21 -> 3947.4 | K21: =I21/2 -> 459 | L21: =K21*E21 -> 1973.7
A22: 10 | B22: SOL-PL-VAS-19 | C22: ML 007314-090-0 | D22: BONIFICO | E22: 4.6 | F22: 30 | G22: =F22*5 -> 150 | H22: =G22*E22 -> 690 | I22: 918 | J22: =I22*E22 -> 4222.8 | K22: =I22/2 -> 459 | L22: =K22*E22 -> 2111.4
A23: 11 | B23: SOL-PL-ESS-21 | C23: ML 007314-090-0 | D23: BLUE | E23: 4.8 | F23: 30 | G23: =F23*5 -> 150 | H23: =G23*E23 -> 720 | I23: 918 | J23: =I23*E23 -> 4406.4 | K23: =I23/2 -> 459 | L23: =K23*E23 -> 2203.2
A24: 12 | B24: SOL-PL-EAS-24 | C24: ML 007314-090-0 | D24: IVORY | E24: 5.2 | F24: 30 | G24: =F24*5 -> 150 | H24: =G24*E24 -> 780 | I24: 918 | J24: =I24*E24 -> 4773.6 | K24: =I24/2 -> 459 | L24: =K24*E24 -> 2386.8
... A54: 42 | B54: SOL-PL-DSSS-164 | C54: 43 007245 85 90 | D54: BONIFICO | E54: 5.4 | F54: 30 | G54: =F54*5 -> 150 | H54: =G54*E54 -> 810 | I54: 918 | J54: =I54*E54 -> 4957.2 | K54: =I54/2 -> 459 | L54: =K54*E54 -> 2478.6
A55: 43 | B55: SOL-PL-VSS-165 | C55: 43 007245 85 90 | D55: LACE | E55: 4 | F55: 30 | G55: 150 | H55: 600 | I55: 918 | J55: 3000 | K55: =I55/2 -> 459 | L55: 1800
A56: TOTAL COST | C56: =COUNTA(PL[[ARTICLE ]]) -> 43 | E56: =SUM(E12:E55) -> 213.1 | H56: =SUM(H12:H55) -> 33683.5
A59: LAGATOLALUREXLACE (L.L)
A60: NO | B60: DESIGN | C60: ARTICLE | D60: QUALITY | E60: QTY (m) | F60: COST PER MT EURO | G60: COST PER MT RM | H60: COST PIECE RM | I60: V.I.P PER MT RM | J60: V.I.P PIECE RM | K60: SELLING PER MT RM | L60: SELLING PIECE RM | M60: SOLD TO
A61: 44 | B61: SOL-LL-DSSS-243 | C61: 7001-140-0 | D61: GOLD/BROWN | E61: 3.4 | F61: 53 | G61: =F61*5 -> 265 | H61: =G61*E61 -> 901 | I61: 1621.8 | J61: =I61*E61 -> 5514.12 | K61: =I61/2 -> 810.9 | L61: =K61*E61 -> 2757.06
A62: 45 | B62: SOL-LL-DUSS-244 | C62: 7001-140-0 | D62: LUREXLACE | E62: 4 | F62: 53 | G62: =F62*5 -> 265 | H62: =G62*E62 -> 1060 | I62: 1621.8 | J62: =I62*E62 -> 6487.2 | K62: =I62/2 -> 810.9 | L62: =K62*E62 -> 3243.6
A63: 46 | B63: SOL-LL-DASS-246 | C63: 7001-140-0 | D63: BALZATO | E63: 4.9 | F63: 53 | G63: =F63*5 -> 265 | H63: =G63*E63 -> 1298.5 | I63: 1621.8 | J63: =I63*E63 -> 7946.82 | K63: =I63/2 -> 810.9 | L63: =K63*E63 -> 3973.41
A64: 47 | B64: SOL-LL-DGSS-247 | C64: 7001-140-0 | D64: SILVER / PEACH | E64: 4.6 | F64: 53 | G64: =F64*5 -> 265 | H64: =G64*E64 -> 1219 | I64: 1621.8 | J64: =I64*E64 -> 7460.28 | K64: =I64/2 -> 810.9 | L64: =K64*E64 -> 3730.14
A65: 48 | B65: SOL-LL-DGSS-248 | C65: 7001-140-0 | D65: PIZZO | E65: 4.2 | F65: 53 | G65: =F65*5 -> 265 | H65: =G65*E65 -> 1113 | I65: 1621.8 | J65: =I65*E65 -> 6811.56 | K65: =I65/2 -> 810.9 | L65: =K65*E65 -> 3405.78
A66: 49 | B66: SOL-LL-DASS-250 | C66: 7316-140-0 | D66: LUREXLACE | E66: 4.9 | F66: 53 | G66: =F66*5 -> 265 | H66: =G66*E66 -> 1298.5 | I66: 1621.8 | J66: =I66*E66 -> 7946.82 | K66: =I66/2 -> 810.9 | L66: =K66*E66 -> 3973.41
A67: 50 | B67: SOL-LL-DGSS-251 | C67: 7316-140-0 | D67: GOLD/ GOLD | E67: 4.6 | F67: 53 | G67: =F67*5 -> 265 | H67: =G67*E67 -> 1219 | I67: 1621.8 | J67: =I67*E67 -> 7460.28 | K67: =I67/2 -> 810.9 | L67: =K67*E67 -> 3730.14
A68: 51 | B68: SOL-LL-DGSS-255 | C68: 7316-140-0 | D68: PIZZO | E68: 4.7 | F68: 53 | G68: =F68*5 -> 265 | H68: =G68*E68 -> 1245.5 | I68: 1621.8 | J68: =I68*E68 -> 7622.46 | K68: =I68/2 -> 810.9 | L68: =K68*E68 -> 3811.23
A69: 52 | B69: SOL-LL-DASS-257 | C69: 7316-140-0 | D69: PIZZO | E69: 4.9 | F69: 53 | G69: =F69*5 -> 265 | H69: =G69*E69 -> 1298.5 | I69: 1621.8 | J69: =I69*E69 -> 7946.82 | K69: =I69/2 -> 810.9 | L69: =K69*E69 -> 3973.41
